Workbook

Sheet numpy_l10_m0_lp10_mp10
B1: kmax1 | C1: kmax1 | D1: kmax1 | E1: kmax1 | F1: kmax2 | G1: kmax2 | H1: kmax2 | I1: kmax2 | J1: kmax3 | K1: kmax3 | L1: kmax3 | M1: kmax3 | N1: kmax4 | O1: kmax4 | P1: kmax4 | Q1: kmax4 | R1: kmax5 | S1: kmax5 | T1: kmax5 | U1: kmax5 | V1: kmax6 | W1: kmax6 | X1: kmax6 | Y1: kmax6 | Z1: kmax7 | AA1: kmax7 | AB1: kmax7 | AC1: kmax7 | AD1: kmax8 | AE1: kmax8 | AF1: kmax8 | AG1: kmax8 | AH1: kmax9 | AI1: kmax9 | AJ1: kmax9 | AK1: kmax9 | AL1: kmax10 | AM1: kmax10 | AN1: kmax10 | AO1: kmax10 | AP1: kmax12 | AQ1: kmax12 | AR1: kmax12 | AS1: kmax12 | AT1: kmax25 | AU1: kmax25 | AV1: kmax25 | AW1: kmax25 | AX1: kmax30 | AY1: kmax30 | AZ1: kmax30 | BA1: kmax30
A2: a | B2: A1 (Re) | C2: A2 (Re) | D2: M0 (Re) | E2: Num (Re) | F2: A1 (Re) | G2: A2 (Re) | H2: M0 (Re) | I2: Num (Re) | J2: A1 (Re) | K2: A2 (Re) | L2: M0 (Re) | M2: Num (Re) | N2: A1 (Re) | O2: A2 (Re) | P2: M0 (Re) | Q2: Num (Re) | R2: A1 (Re) | S2: A2 (Re) | T2: M0 (Re) | U2: Num (Re) | V2: A1 (Re) | W2: A2 (Re) | X2: M0 (Re) | Y2: Num (Re) | Z2: A1 (Re) | AA2: A2 (Re) | AB2: M0 (Re) | AC2: Num (Re) | AD2: A1 (Re) | AE2: A2 (Re) | AF2: M0 (Re) | AG2: Num (Re) | AH2: A1 (Re) | AI2: A2 (Re) | AJ2: M0 (Re) | AK2: Num (Re) | AL2: A1 (Re) | AM2: A2 (Re) | AN2: M0 (Re) | AO2: Num (Re) | AP2: A1 (Re) | AQ2: A2 (Re) | AR2: M0 (Re) | AS2: Num (Re) | AT2: A1 (Re) | AU2: A2 (Re) | AV2: M0 (Re) | AW2: Num (Re) | AX2: A1 (Re) | AY2: A2 (Re) | AZ2: M0 (Re) | BA2: Num (Re)
A3: 0 | B3: 0.095238095 | C3: 0.095238095 | D3: 0.095238095 | E3: 0.095238095 | F3: 0.095238095 | G3: 0.095238095 | H3: 0.095238095 | I3: 0.095238095 | J3: 0.095238095 | K3: 0.095238095 | L3: 0.095238095 | M3: 0.095238095 | N3: 0.095238095 | O3: 0.095238095 | P3: 0.095238095 | Q3: 0.095238095 | R3: 0.095238095 | S3: 0.095238095 | T3: 0.095238095 | U3: 0.095238095 | V3: 0.095238095 | W3: 0.095238095 | X3: 0.095238095 | Y3: 0.095238095 | Z3: 0.095238095 | AA3: 0.095238095 | AB3: 0.095238095 | AC3: 0.095238095 | AD3: 0.095238095 | AE3: 0.095238095 | AF3: 0.095238095 | AG3: 0.095238095 | AH3: 0.095238095 | AI3: 0.095238095 | AJ3: 0.095238095 | AK3: 0.095238095 | AL3: 0.095238095 | AM3: 0.095238095 | AN3: 0.095238095 | AO3: 0.095238095 | AP3: 0.095238095 | AQ3: 0.095238095 | AR3: 0.095238095 | AS3: 0.095238095 | AT3: 0.095238095 | AU3: 0.095238095 | AV3: 0.095238095 | AW3: 0.095238095 | AX3: 0.095238095 | AY3: 0.095238095 | AZ3: 0.095238095 | BA3: 0.095238095
A4: 0.2 | B4: 0.094604443 | C4: 0.094604443 | D4: 0.094285924 | E4: 0.094285924 | F4: 0.094285716 | G4: 0.094285716 | H4: 0.094285924 | I4: 0.094285924 | J4: 0.094285716 | K4: 0.094285716 | L4: 0.094285924 | M4: 0.094285924 | N4: 0.094285924 | O4: 0.094285924 | P4: 0.094285924 | Q4: 0.094285924 | R4: 0.094285924 | S4: 0.094285924 | T4: 0.094285924 | U4: 0.094285924 | V4: 0.094285924 | W4: 0.094285924 | X4: 0.094285924 | Y4: 0.094285924 | Z4: 0.094285924 | AA4: 0.094285924 | AB4: 0.094285924 | AC4: 0.094285924 | AD4: 0.094285924 | AE4: 0.094285924 | AF4: 0.094285924 | AG4: 0.094285924 | AH4: 0.094285924 | AI4: 0.094285924 | AJ4: 0.094285924 | AK4: 0.094285924 | AL4: 0.094285924 | AM4: 0.094285924 | AN4: 0.094285924 | AO4: 0.094285924 | AP4: 0.094285924 | AQ4: 0.094285924 | AR4: 0.094285924 | AS4: 0.094285924 | AT4: 0.094285924 | AU4: 0.094285924 | AV4: 0.094285924 | AW4: 0.094285924 | AX4: 0.094285924 | AY4: 0.094285924 | AZ4: 0.094285924 | BA4: 0.094285924
A5: 0.4 | B5: 0.092718653 | C5: 0.092718653 | D5: 0.091457955 | E5: 0.091457955 | F5: 0.091454642 | G5: 0.091454642 | H5: 0.091457955 | I5: 0.091457955 | J5: 0.091454642 | K5: 0.091454642 | L5: 0.091457955 | M5: 0.091457955 | N5: 0.091457959 | O5: 0.091457959 | P5: 0.091457955 | Q5: 0.091457955 | R5: 0.091457959 | S5: 0.091457959 | T5: 0.091457955 | U5: 0.091457955 | V5: 0.091457955 | W5: 0.091457955 | X5: 0.091457955 | Y5: 0.091457955 | Z5: 0.091457955 | AA5: 0.091457955 | AB5: 0.091457955 | AC5: 0.091457955 | AD5: 0.091457955 | AE5: 0.091457955 | AF5: 0.091457955 | AG5: 0.091457955 | AH5: 0.091457955 | AI5: 0.091457955 | AJ5: 0.091457955 | AK5: 0.091457955 | AL5: 0.091457955 | AM5: 0.091457955 | AN5: 0.091457955 | AO5: 0.091457955 | AP5: 0.091457955 | AQ5: 0.091457955 | AR5: 0.091457955 | AS5: 0.091457955 | AT5: 0.091457955 | AU5: 0.091457955 | AV5: 0.091457955 | AW5: 0.091457955 | AX5: 0.091457955 | AY5: 0.091457955 | AZ5: 0.091457955 | BA5: 0.091457955
A6: 0.6 | B6: 0.089625789 | C6: 0.089625789 | D6: 0.08683887 | E6: 0.08683887 | F6: 0.08682227 | G6: 0.08682227 | H6: 0.08683887 | I6: 0.08683887 | J6: 0.08682227 | K6: 0.08682227 | L6: 0.08683887 | M6: 0.08683887 | N6: 0.086838914 | O6: 0.086838914 | P6: 0.08683887 | Q6: 0.08683887 | R6: 0.086838914 | S6: 0.086838914 | T6: 0.08683887 | U6: 0.08683887 | V6: 0.08683887 | W6: 0.08683887 | X6: 0.08683887 | Y6: 0.08683887 | Z6: 0.08683887 | AA6: 0.08683887 | AB6: 0.08683887 | AC6: 0.08683887 | AD6: 0.08683887 | AE6: 0.08683887 | AF6: 0.08683887 | AG6: 0.08683887 | AH6: 0.08683887 | AI6: 0.08683887 | AJ6: 0.08683887 | AK6: 0.08683887 | AL6: 0.08683887 | AM6: 0.08683887 | AN6: 0.08683887 | AO6: 0.08683887 | AP6: 0.08683887 | AQ6: 0.08683887 | AR6: 0.08683887 | AS6: 0.08683887 | AT6: 0.08683887 | AU6: 0.08683887 | AV6: 0.08683887 | AW6: 0.08683887 | AX6: 0.08683887 | AY6: 0.08683887 | AZ6: 0.08683887 | BA6: 0.08683887
A7: 0.8 | B7: 0.085399535 | C7: 0.085399535 | D7: 0.08056667 | E7: 0.08056667 | F7: 0.080514977 | G7: 0.080514977 | H7: 0.08056667 | I7: 0.08056667 | J7: 0.080514977 | K7: 0.080514977 | L7: 0.08056667 | M7: 0.08056667 | N7: 0.080566911 | O7: 0.080566911 | P7: 0.08056667 | Q7: 0.08056667 | R7: 0.080566911 | S7: 0.080566911 | T7: 0.08056667 | U7: 0.08056667 | V7: 0.080566669 | W7: 0.080566669 | X7: 0.08056667 | Y7: 0.08056667 | Z7: 0.080566669 | AA7: 0.080566669 | AB7: 0.08056667 | AC7: 0.08056667 | AD7: 0.08056667 | AE7: 0.08056667 | AF7: 0.08056667 | AG7: 0.08056667 | AH7: 0.08056667 | AI7: 0.08056667 | AJ7: 0.08056667 | AK7: 0.08056667 | AL7: 0.08056667 | AM7: 0.08056667 | AN7: 0.08056667 | AO7: 0.08056667 | AP7: 0.08056667 | AQ7: 0.08056667 | AR7: 0.08056667 | AS7: 0.08056667 | AT7: 0.08056667 | AU7: 0.08056667 | AV7: 0.08056667 | AW7: 0.08056667 | AX7: 0.08056667 | AY7: 0.08056667 | AZ7: 0.08056667 | BA7: 0.08056667
A8: 1 | B8: 0.080140094 | C8: 0.080140094 | D8: 0.072828085 | E8: 0.072828085 | F8: 0.07270427 | G8: 0.07270427 | H8: 0.072828085 | I8: 0.072828085 | J8: 0.07270427 | K8: 0.07270427 | L8: 0.072828085 | M8: 0.072828085 | N8: 0.072828991 | O8: 0.072828991 | P8: 0.072828085 | Q8: 0.072828085 | R8: 0.072828991 | S8: 0.072828991 | T8: 0.072828085 | U8: 0.072828085 | V8: 0.072828081 | W8: 0.072828081 | X8: 0.072828085 | Y8: 0.072828085 | Z8: 0.072828081 | AA8: 0.072828081 | AB8: 0.072828085 | AC8: 0.072828085 | AD8: 0.072828085 | AE8: 0.072828085 | AF8: 0.072828085 | AG8: 0.072828085 | AH8: 0.072828085 | AI8: 0.072828085 | AJ8: 0.072828085 | AK8: 0.072828085 | AL8: 0.072828085 | AM8: 0.072828085 | AN8: 0.072828085 | AO8: 0.072828085 | AP8: 0.072828085 | AQ8: 0.072828085 | AR8: 0.072828085 | AS8: 0.072828085 | AT8: 0.072828085 | AU8: 0.072828085 | AV8: 0.072828085 | AW8: 0.072828085 | AX8: 0.072828085 | AY8: 0.072828085 | AZ8: 0.072828085 | BA8: 0.072828085
A9: 1.2 | B9: 0.073971356 | C9: 0.073971356 | D9: 0.063852379 | E9: 0.063852379 | F9: 0.063601583 | G9: 0.063601583 | H9: 0.063852379 | I9: 0.063852379 | J9: 0.063601583 | K9: 0.063601583 | L9: 0.063852379 | M9: 0.063852379 | N9: 0.06385504 | O9: 0.06385504 | P9: 0.063852379 | Q9: 0.063852379 | R9: 0.06385504 | S9: 0.06385504 | T9: 0.063852379 | U9: 0.063852379 | V9: 0.063852363 | W9: 0.063852363 | X9: 0.063852379 | Y9: 0.063852379 | Z9: 0.063852363 | AA9: 0.063852363 | AB9: 0.063852379 | AC9: 0.063852379 | AD9: 0.063852379 | AE9: 0.063852379 | AF9: 0.063852379 | AG9: 0.063852379 | AH9: 0.063852379 | AI9: 0.063852379 | AJ9: 0.063852379 | AK9: 0.063852379 | AL9: 0.063852379 | AM9: 0.063852379 | AN9: 0.063852379 | AO9: 0.063852379 | AP9: 0.063852379 | AQ9: 0.063852379 | AR9: 0.063852379 | AS9: 0.063852379 | AT9: 0.063852379 | AU9: 0.063852379 | AV9: 0.063852379 | AW9: 0.063852379 | AX9: 0.063852379 | AY9: 0.063852379 | AZ9: 0.063852379 | BA9: 0.063852379
A10: 1.4 | B10: 0.067037397 | C10: 0.067037397 | D10: 0.053903759 | E10: 0.053903759 | F10: 0.053451878 | G10: 0.053451878 | H10: 0.053903759 | I10: 0.053903759 | J10: 0.053451878 | K10: 0.053451878 | L10: 0.053903759 | M10: 0.053903759 | N10: 0.053910338 | O10: 0.053910338 | P10: 0.053903759 | Q10: 0.053903759 | R10: 0.053910338 | S10: 0.053910338 | T10: 0.053903759 | U10: 0.053903759 | V10: 0.053903705 | W10: 0.053903705 | X10: 0.053903759 | Y10: 0.053903759 | Z10: 0.053903705 | AA10: 0.053903705 | AB10: 0.053903759 | AC10: 0.053903759 | AD10: 0.053903759 | AE10: 0.053903759 | AF10: 0.053903759 | AG10: 0.053903759 | AH10: 0.053903759 | AI10: 0.053903759 | AJ10: 0.053903759 | AK10: 0.053903759 | AL10: 0.053903759 | AM10: 0.053903759 | AN10: 0.053903759 | AO10: 0.053903759 | AP10: 0.053903759 | AQ10: 0.053903759 | AR10: 0.053903759 | AS10: 0.053903759 | AT10: 0.053903759 | AU10: 0.053903759 | AV10: 0.053903759 | AW10: 0.053903759 | AX10: 0.053903759 | AY10: 0.053903759 | AZ10: 0.053903759 | BA10: 0.053903759
A11: 1.6 | B11: 0.059498429 | C11: 0.059498429 | D11: 0.043272652 | E11: 0.043272652 | F11: 0.04252625 | G11: 0.04252625 | H11: 0.043272652 | I11: 0.043272652 | J11: 0.04252625 | K11: 0.04252625 | L11: 0.043272652 | M11: 0.043272652 | N11: 0.043286982 | O11: 0.043286982 | P11: 0.043272652 | Q11: 0.043272652 | R11: 0.043286982 | S11: 0.043286982 | T11: 0.043272652 | U11: 0.043272652 | V11: 0.043272499 | W11: 0.043272499 | X11: 0.043272652 | Y11: 0.043272652 | Z11: 0.043272499 | AA11: 0.043272499 | AB11: 0.043272652 | AC11: 0.043272652 | AD11: 0.043272653 | AE11: 0.043272653 | AF11: 0.043272652 | AG11: 0.043272652 | AH11: 0.043272653 | AI11: 0.043272653 | AJ11: 0.043272652 | AK11: 0.043272652 | AL11: 0.043272652 | AM11: 0.043272652 | AN11: 0.043272652 | AO11: 0.043272652 | AP11: 0.043272652 | AQ11: 0.043272652 | AR11: 0.043272652 | AS11: 0.043272652 | AT11: 0.043272652 | AU11: 0.043272652 | AV11: 0.043272652 | AW11: 0.043272652 | AX11: 0.043272652 | AY11: 0.043272652 | AZ11: 0.043272652 | BA11: 0.043272652
A12: 1.8 | B12: 0.05152633 | C12: 0.05152633 | D12: 0.032266167 | E12: 0.032266167 | F12: 0.031113787 | G12: 0.031113787 | H12: 0.032266167 | I12: 0.032266167 | J12: 0.031113787 | K12: 0.031113787 | L12: 0.032266167 | M12: 0.032266167 | N12: 0.032294478 | O12: 0.032294478 | P12: 0.032266167 | Q12: 0.032266167 | R12: 0.032294478 | S12: 0.032294478 | T12: 0.032266167 | U12: 0.032266167 | V12: 0.032265782 | W12: 0.032265782 | X12: 0.032266167 | Y12: 0.032266167 | Z12: 0.032265782 | AA12: 0.032265782 | AB12: 0.032266167 | AC12: 0.032266167 | AD12: 0.03226617 | AE12: 0.03226617 | AF12: 0.032266167 | AG12: 0.032266167 | AH12: 0.03226617 | AI12: 0.03226617 | AJ12: 0.032266167 | AK12: 0.032266167 | AL12: 0.032266167 | AM12: 0.032266167 | AN12: 0.032266167 | AO12: 0.032266167 | AP12: 0.032266167 | AQ12: 0.032266167 | AR12: 0.032266167 | AS12: 0.032266167 | AT12: 0.032266167 | AU12: 0.032266167 | AV12: 0.032266167 | AW12: 0.032266167 | AX12: 0.032266167 | AY12: 0.032266167 | AZ12: 0.032266167 | BA12: 0.032266167
A13: 2 | B13: 0.043299878 | C13: 0.043299878 | D13: 0.02119805 | E13: 0.02119805 | F13: 0.019512938 | G13: 0.019512938 | H13: 0.02119805 | I13: 0.02119805 | J13: 0.019512938 | K13: 0.019512938 | L13: 0.02119805 | M13: 0.02119805 | N13: 0.021249802 | O13: 0.021249802 | P13: 0.02119805 | Q13: 0.02119805 | R13: 0.021249802 | S13: 0.021249802 | T13: 0.02119805 | U13: 0.02119805 | V13: 0.021197175 | W13: 0.021197175 | X13: 0.02119805 | Y13: 0.02119805 | Z13: 0.021197175 | AA13: 0.021197175 | AB13: 0.02119805 | AC13: 0.02119805 | AD13: 0.02119806 | AE13: 0.02119806 | AF13: 0.02119805 | AG13: 0.02119805 | AH13: 0.02119806 | AI13: 0.02119806 | AJ13: 0.02119805 | AK13: 0.02119805 | AL13: 0.02119805 | AM13: 0.02119805 | AN13: 0.02119805 | AO13: 0.02119805 | AP13: 0.02119805 | AQ13: 0.02119805 | AR13: 0.02119805 | AS13: 0.02119805 | AT13: 0.02119805 | AU13: 0.02119805 | AV13: 0.02119805 | AW13: 0.02119805 | AX13: 0.02119805 | AY13: 0.02119805 | AZ13: 0.02119805 | BA13: 0.02119805
A14: 2.2 | B14: 0.034999844 | C14: 0.034999844 | D14: 0.010378504 | E14: 0.010378504 | F14: 0.0080226593 | G14: 0.0080226593 | H14: 0.010378504 | I14: 0.010378504 | J14: 0.0080226593 | K14: 0.0080226593 | L14: 0.010378504 | M14: 0.010378504 | N14: 0.010467285 | O14: 0.010467285 | P14: 0.010378504 | Q14: 0.010378504 | R14: 0.010467285 | S14: 0.010467285 | T14: 0.010378504 | U14: 0.010378504 | V14: 0.010376674 | W14: 0.010376674 | X14: 0.010378504 | Y14: 0.010378504 | Z14: 0.010376674 | AA14: 0.010376674 | AB14: 0.010378504 | AC14: 0.010378504 | AD14: 0.010378528 | AE14: 0.010378528 | AF14: 0.010378504 | AG14: 0.010378504 | AH14: 0.010378528 | AI14: 0.010378528 | AJ14: 0.010378504 | AK14: 0.010378504 | AL14: 0.010378504 | AM14: 0.010378504 | AN14: 0.010378504 | AO14: 0.010378504 | AP14: 0.010378504 | AQ14: 0.010378504 | AR14: 0.010378504 | AS14: 0.010378504 | AT14: 0.010378504 | AU14: 0.010378504 | AV14: 0.010378504 | AW14: 0.010378504 | AX14: 0.010378504 | AY14: 0.010378504 | AZ14: 0.010378504 | BA14: 0.010378504
... A253: 50 | B253: -0.0004997616 | C253: -0.0004997616 | D253: 0.003137029 | E253: 0.003137029 | F253: -0.0009891988 | G253: -0.0009891988 | H253: 0.003137029 | I253: 0.003137029 | J253: -0.0009891988 | K253: -0.0009891988 | L253: 0.003137029 | M253: 0.003137029 | N253: -0.0011507387 | O253: -0.0011507387 | P253: 0.003137029 | Q253: 0.003137029 | R253: -0.0011507387 | S253: -0.0011507387 | T253: 0.003137029 | U253: 0.003137029 | V253: -0.000756571 | W253: -0.000756571 | X253: 0.003137029 | Y253: 0.003137029 | Z253: -0.000756571 | AA253: -0.000756571 | AB253: 0.003137029 | AC253: 0.003137029 | AD253: 0.0004176014 | AE253: 0.0004176016 | AF253: 0.003137029 | AG253: 0.003137029 | AH253: 0.0004176014 | AI253: 0.0004176016 | AJ253: 0.003137029 | AK253: 0.003137029 | AL253: 0.0025197067 | AM253: 0.002519707 | AN253: 0.003137029 | AO253: 0.003137029 | AP253: 0.0054719587 | AQ253: 0.0054719567 | AR253: 0.003137029 | AS253: 0.003137029 | AT253: 0.0033836836 | AU253: 0.00340518 | AV253: 0.003137029 | AW253: 0.003137029 | AX253: -0.0023885402 | AY253: 0.0088766129 | AZ253: 0.003137029 | BA253: 0.003137029

Sheet delta - numpy_l10_m0_lp10_mp0
B1: kmax1 | C1: kmax1 | D1: kmax1 | E1: kmax2 | F1: kmax2 | G1: kmax2 | H1: kmax3 | I1: kmax3 | J1: kmax3 | K1: kmax4 | L1: kmax4 | M1: kmax4 | N1: kmax5 | O1: kmax5 | P1: kmax5 | Q1: kmax6 | R1: kmax6 | S1: kmax6 | T1: kmax7 | U1: kmax7 | V1: kmax7 | W1: kmax8 | X1: kmax8 | Y1: kmax8 | Z1: kmax9 | AA1: kmax9 | AB1: kmax9 | AC1: kmax10 | AD1: kmax10 | AE1: kmax10 | AF1: kmax12 | AG1: kmax12 | AH1: kmax12 | AI1: kmax25 | AJ1: kmax25 | AK1: kmax25 | AL1: kmax30 | AM1: kmax30 | AN1: kmax30
A2: a | B2: |A1 - A2| | C2: |A1 - M0| | D2: |M0 - Num| | E2: |A1 - A2| | F2: |A1 - M0| | G2: |M0 - Num| | H2: |A1 - A2| | I2: |A1 - M0| | J2: |M0 - Num| | K2: |A1 - A2| | L2: |A1 - M0| | M2: |M0 - Num| | N2: |A1 - A2| | O2: |A1 - M0| | P2: |M0 - Num| | Q2: |A1 - A2| | R2: |A1 - M0| | S2: |M0 - Num| | T2: |A1 - A2| | U2: |A1 - M0| | V2: |M0 - Num| | W2: |A1 - A2| | X2: |A1 - M0| | Y2: |M0 - Num| | Z2: |A1 - A2| | AA2: |A1 - M0| | AB2: |M0 - Num| | AC2: |A1 - A2| | AD2: |A1 - M0| | AE2: |M0 - Num| | AF2: |A1 - A2| | AG2: |A1 - M0| | AH2: |M0 - Num| | AI2: |A1 - A2| | AJ2: |A1 - M0| | AK2: |M0 - Num| | AL2: |A1 - A2| | AM2: |A1 - M0| | AN2: |M0 - Num|
A3: 0 | B3: =ABS(numpy_l10_m0_lp10_mp10!B3-numpy_l10_m0_lp10_mp10!C3) -> 0 | C3: =ABS(numpy_l10_m0_lp10_mp10!B3-numpy_l10_m0_lp10_mp10!D3) -> 0 | D3: =ABS(numpy_l10_m0_lp10_mp10!D3-numpy_l10_m0_lp10_mp10!E3) -> 0 | E3: =ABS(numpy_l10_m0_lp10_mp10!F3-numpy_l10_m0_lp10_mp10!G3) -> 0 | F3: =ABS(numpy_l10_m0_lp10_mp10!F3-numpy_l10_m0_lp10_mp10!H3) -> 0 | G3: =ABS(numpy_l10_m0_lp10_mp10!H3-numpy_l10_m0_lp10_mp10!I3) -> 0 | H3: =ABS(numpy_l10_m0_lp10_mp10!J3-numpy_l10_m0_lp10_mp10!K3) -> 0 | I3: =ABS(numpy_l10_m0_lp10_mp10!J3-numpy_l10_m0_lp10_mp10!L3) -> 0 | J3: =ABS(numpy_l10_m0_lp10_mp10!L3-numpy_l10_m0_lp10_mp10!M3) -> 0 | K3: =ABS(numpy_l10_m0_lp10_mp10!N3-numpy_l10_m0_lp10_mp10!O3) -> 0 | L3: =ABS(numpy_l10_m0_lp10_mp10!N3-numpy_l10_m0_lp10_mp10!P3) -> 0 | M3: =ABS(numpy_l10_m0_lp10_mp10!P3-numpy_l10_m0_lp10_mp10!Q3) -> 0 | N3: =ABS(numpy_l10_m0_lp10_mp10!R3-numpy_l10_m0_lp10_mp10!S3) -> 0 | O3: =ABS(numpy_l10_m0_lp10_mp10!R3-numpy_l10_m0_lp10_mp10!T3) -> 0 | P3: =ABS(numpy_l10_m0_lp10_mp10!T3-numpy_l10_m0_lp10_mp10!U3) -> 0 | Q3: =ABS(numpy_l10_m0_lp10_mp10!V3-numpy_l10_m0_lp10_mp10!W3) -> 0 | R3: =ABS(numpy_l10_m0_lp10_mp10!V3-numpy_l10_m0_lp10_mp10!X3) -> 0 | S3: =ABS(numpy_l10_m0_lp10_mp10!X3-numpy_l10_m0_lp10_mp10!Y3) -> 0 | T3: =ABS(numpy_l10_m0_lp10_mp10!Z3-numpy_l10_m0_lp10_mp10!AA3) -> 0 | U3: =ABS(numpy_l10_m0_lp10_mp10!Z3-numpy_l10_m0_lp10_mp10!AB3) -> 0 | V3: =ABS(numpy_l10_m0_lp10_mp10!AB3-numpy_l10_m0_lp10_mp10!AC3) -> 0 | W3: =ABS(numpy_l10_m0_lp10_mp10!AD3-numpy_l10_m0_lp10_mp10!AE3) -> 0 | X3: =ABS(numpy_l10_m0_lp10_mp10!AD3-numpy_l10_m0_lp10_mp10!AF3) -> 0 | Y3: =ABS(numpy_l10_m0_lp10_mp10!AF3-numpy_l10_m0_lp10_mp10!AG3) -> 0 | Z3: =ABS(numpy_l10_m0_lp10_mp10!AH3-numpy_l10_m0_lp10_mp10!AI3) -> 0 | AA3: =ABS(numpy_l10_m0_lp10_mp10!AH3-numpy_l10_m0_lp10_mp10!AJ3) -> 0 | AB3: =ABS(numpy_l10_m0_lp10_mp10!AJ3-numpy_l10_m0_lp10_mp10!AK3) -> 0 | AC3: =ABS(numpy_l10_m0_lp10_mp10!AL3-numpy_l10_m0_lp10_mp10!AM3) -> 0 | AD3: =ABS(numpy_l10_m0_lp10_mp10!AL3-numpy_l10_m0_lp10_mp10!AN3) -> 0 | AE3: =ABS(numpy_l10_m0_lp10_mp10!AN3-numpy_l10_m0_lp10_mp10!AO3) -> 0 | AF3: =ABS(numpy_l10_m0_lp10_mp10!AP3-numpy_l10_m0_lp10_mp10!AQ3) -> 0 | AG3: =ABS(numpy_l10_m0_lp10_mp10!AP3-numpy_l10_m0_lp10_mp10!AR3) -> 0 | AH3: =ABS(numpy_l10_m0_lp10_mp10!AR3-numpy_l10_m0_lp10_mp10!AS3) -> 0 | AI3: =ABS(numpy_l10_m0_lp10_mp10!AT3-numpy_l10_m0_lp10_mp10!AU3) -> 0 | AJ3: =ABS(numpy_l10_m0_lp10_mp10!AT3-numpy_l10_m0_lp10_mp10!AV3) -> 0 | AK3: =ABS(numpy_l10_m0_lp10_mp10!AV3-numpy_l10_m0_lp10_mp10!AW3) -> 0 | AL3: =ABS(numpy_l10_m0_lp10_mp10!AX3-numpy_l10_m0_lp10_mp10!AY3) -> 0 | AM3: =ABS(numpy_l10_m0_lp10_mp10!AX3-numpy_l10_m0_lp10_mp10!AZ3) -> 0 | AN3: =ABS(numpy_l10_m0_lp10_mp10!AZ3-numpy_l10_m0_lp10_mp10!BA3) -> 0
A4: 0.2 | B4: =ABS(numpy_l10_m0_lp10_mp10!B4-numpy_l10_m0_lp10_mp10!C4) -> 0 | C4: =ABS(numpy_l10_m0_lp10_mp10!B4-numpy_l10_m0_lp10_mp10!D4) -> 0.000318519 | D4: =ABS(numpy_l10_m0_lp10_mp10!D4-numpy_l10_m0_lp10_mp10!E4) -> 0 | E4: =ABS(numpy_l10_m0_lp10_mp10!F4-numpy_l10_m0_lp10_mp10!G4) -> 0 | F4: =ABS(numpy_l10_m0_lp10_mp10!F4-numpy_l10_m0_lp10_mp10!H4) -> 2.084e-07 | G4: =ABS(numpy_l10_m0_lp10_mp10!H4-numpy_l10_m0_lp10_mp10!I4) -> 0 | H4: =ABS(numpy_l10_m0_lp10_mp10!J4-numpy_l10_m0_lp10_mp10!K4) -> 0 | I4: =ABS(numpy_l10_m0_lp10_mp10!J4-numpy_l10_m0_lp10_mp10!L4) -> 2.084e-07 | J4: =ABS(numpy_l10_m0_lp10_mp10!L4-numpy_l10_m0_lp10_mp10!M4) -> 0 | K4: =ABS(numpy_l10_m0_lp10_mp10!N4-numpy_l10_m0_lp10_mp10!O4) -> 0 | L4: =ABS(numpy_l10_m0_lp10_mp10!N4-numpy_l10_m0_lp10_mp10!P4) -> 1.0000001e-10 | M4: =ABS(numpy_l10_m0_lp10_mp10!P4-numpy_l10_m0_lp10_mp10!Q4) -> 0 | N4: =ABS(numpy_l10_m0_lp10_mp10!R4-numpy_l10_m0_lp10_mp10!S4) -> 0 | O4: =ABS(numpy_l10_m0_lp10_mp10!R4-numpy_l10_m0_lp10_mp10!T4) -> 1.0000001e-10 | P4: =ABS(numpy_l10_m0_lp10_mp10!T4-numpy_l10_m0_lp10_mp10!U4) -> 0 | Q4: =ABS(numpy_l10_m0_lp10_mp10!V4-numpy_l10_m0_lp10_mp10!W4) -> 0 | R4: =ABS(numpy_l10_m0_lp10_mp10!V4-numpy_l10_m0_lp10_mp10!X4) -> 0 | S4: =ABS(numpy_l10_m0_lp10_mp10!X4-numpy_l10_m0_lp10_mp10!Y4) -> 0 | T4: =ABS(numpy_l10_m0_lp10_mp10!Z4-numpy_l10_m0_lp10_mp10!AA4) -> 0 | U4: =ABS(numpy_l10_m0_lp10_mp10!Z4-numpy_l10_m0_lp10_mp10!AB4) -> 0 | V4: =ABS(numpy_l10_m0_lp10_mp10!AB4-numpy_l10_m0_lp10_mp10!AC4) -> 0 | W4: =ABS(numpy_l10_m0_lp10_mp10!AD4-numpy_l10_m0_lp10_mp10!AE4) -> 0 | X4: =ABS(numpy_l10_m0_lp10_mp10!AD4-numpy_l10_m0_lp10_mp10!AF4) -> 0 | Y4: =ABS(numpy_l10_m0_lp10_mp10!AF4-numpy_l10_m0_lp10_mp10!AG4) -> 0 | Z4: =ABS(numpy_l10_m0_lp10_mp10!AH4-numpy_l10_m0_lp10_mp10!AI4) -> 0 | AA4: =ABS(numpy_l10_m0_lp10_mp10!AH4-numpy_l10_m0_lp10_mp10!AJ4) -> 0 | AB4: =ABS(numpy_l10_m0_lp10_mp10!AJ4-numpy_l10_m0_lp10_mp10!AK4) -> 0 | AC4: =ABS(numpy_l10_m0_lp10_mp10!AL4-numpy_l10_m0_lp10_mp10!AM4) -> 0 | AD4: =ABS(numpy_l10_m0_lp10_mp10!AL4-numpy_l10_m0_lp10_mp10!AN4) -> 0 | AE4: =ABS(numpy_l10_m0_lp10_mp10!AN4-numpy_l10_m0_lp10_mp10!AO4) -> 0 | AF4: =ABS(numpy_l10_m0_lp10_mp10!AP4-numpy_l10_m0_lp10_mp10!AQ4) -> 0 | AG4: =ABS(numpy_l10_m0_lp10_mp10!AP4-numpy_l10_m0_lp10_mp10!AR4) -> 0 | AH4: =ABS(numpy_l10_m0_lp10_mp10!AR4-numpy_l10_m0_lp10_mp10!AS4) -> 0 | AI4: =ABS(numpy_l10_m0_lp10_mp10!AT4-numpy_l10_m0_lp10_mp10!AU4) -> 0 | AJ4: =ABS(numpy_l10_m0_lp10_mp10!AT4-numpy_l10_m0_lp10_mp10!AV4) -> 0 | AK4: =ABS(numpy_l10_m0_lp10_mp10!AV4-numpy_l10_m0_lp10_mp10!AW4) -> 0 | AL4: =ABS(numpy_l10_m0_lp10_mp10!AX4-numpy_l10_m0_lp10_mp10!AY4) -> 0 | AM4: =ABS(numpy_l10_m0_lp10_mp10!AX4-numpy_l10_m0_lp10_mp10!AZ4) -> 0 | AN4: =ABS(numpy_l10_m0_lp10_mp10!AZ4-numpy_l10_m0_lp10_mp10!BA4) -> 0
A5: 0.4 | B5: =ABS(numpy_l10_m0_lp10_mp10!B5-numpy_l10_m0_lp10_mp10!C5) -> 0 | C5: =ABS(numpy_l10_m0_lp10_mp10!B5-numpy_l10_m0_lp10_mp10!D5) -> 0.0012606976 | D5: =ABS(numpy_l10_m0_lp10_mp10!D5-numpy_l10_m0_lp10_mp10!E5) -> 0 | E5: =ABS(numpy_l10_m0_lp10_mp10!F5-numpy_l10_m0_lp10_mp10!G5) -> 0 | F5: =ABS(numpy_l10_m0_lp10_mp10!F5-numpy_l10_m0_lp10_mp10!H5) -> 3.3138e-06 | G5: =ABS(numpy_l10_m0_lp10_mp10!H5-numpy_l10_m0_lp10_mp10!I5) -> 0 | H5: =ABS(numpy_l10_m0_lp10_mp10!J5-numpy_l10_m0_lp10_mp10!K5) -> 0 | I5: =ABS(numpy_l10_m0_lp10_mp10!J5-numpy_l10_m0_lp10_mp10!L5) -> 3.3138e-06 | J5: =ABS(numpy_l10_m0_lp10_mp10!L5-numpy_l10_m0_lp10_mp10!M5) -> 0 | K5: =ABS(numpy_l10_m0_lp10_mp10!N5-numpy_l10_m0_lp10_mp10!O5) -> 0 | L5: =ABS(numpy_l10_m0_lp10_mp10!N5-numpy_l10_m0_lp10_mp10!P5) -> 3.9e-09 | M5: =ABS(numpy_l10_m0_lp10_mp10!P5-numpy_l10_m0_lp10_mp10!Q5) -> 0 | N5: =ABS(numpy_l10_m0_lp10_mp10!R5-numpy_l10_m0_lp10_mp10!S5) -> 0 | O5: =ABS(numpy_l10_m0_lp10_mp10!R5-numpy_l10_m0_lp10_mp10!T5) -> 3.9e-09 | P5: =ABS(numpy_l10_m0_lp10_mp10!T5-numpy_l10_m0_lp10_mp10!U5) -> 0 | Q5: =ABS(numpy_l10_m0_lp10_mp10!V5-numpy_l10_m0_lp10_mp10!W5) -> 0 | R5: =ABS(numpy_l10_m0_lp10_mp10!V5-numpy_l10_m0_lp10_mp10!X5) -> 0 | S5: =ABS(numpy_l10_m0_lp10_mp10!X5-numpy_l10_m0_lp10_mp10!Y5) -> 0 | T5: =ABS(numpy_l10_m0_lp10_mp10!Z5-numpy_l10_m0_lp10_mp10!AA5) -> 0 | U5: =ABS(numpy_l10_m0_lp10_mp10!Z5-numpy_l10_m0_lp10_mp10!AB5) -> 0 | V5: =ABS(numpy_l10_m0_lp10_mp10!AB5-numpy_l10_m0_lp10_mp10!AC5) -> 0 | W5: =ABS(numpy_l10_m0_lp10_mp10!AD5-numpy_l10_m0_lp10_mp10!AE5) -> 0 | X5: =ABS(numpy_l10_m0_lp10_mp10!AD5-numpy_l10_m0_lp10_mp10!AF5) -> 0 | Y5: =ABS(numpy_l10_m0_lp10_mp10!AF5-numpy_l10_m0_lp10_mp10!AG5) -> 0 | Z5: =ABS(numpy_l10_m0_lp10_mp10!AH5-numpy_l10_m0_lp10_mp10!AI5) -> 0 | AA5: =ABS(numpy_l10_m0_lp10_mp10!AH5-numpy_l10_m0_lp10_mp10!AJ5) -> 0 | AB5: =ABS(numpy_l10_m0_lp10_mp10!AJ5-numpy_l10_m0_lp10_mp10!AK5) -> 0 | AC5: =ABS(numpy_l10_m0_lp10_mp10!AL5-numpy_l10_m0_lp10_mp10!AM5) -> 0 | AD5: =ABS(numpy_l10_m0_lp10_mp10!AL5-numpy_l10_m0_lp10_mp10!AN5) -> 0 | AE5: =ABS(numpy_l10_m0_lp10_mp10!AN5-numpy_l10_m0_lp10_mp10!AO5) -> 0 | AF5: =ABS(numpy_l10_m0_lp10_mp10!AP5-numpy_l10_m0_lp10_mp10!AQ5) -> 0 | AG5: =ABS(numpy_l10_m0_lp10_mp10!AP5-numpy_l10_m0_lp10_mp10!AR5) -> 0 | AH5: =ABS(numpy_l10_m0_lp10_mp10!AR5-numpy_l10_m0_lp10_mp10!AS5) -> 0 | AI5: =ABS(numpy_l10_m0_lp10_mp10!AT5-numpy_l10_m0_lp10_mp10!AU5) -> 0 | AJ5: =ABS(numpy_l10_m0_lp10_mp10!AT5-numpy_l10_m0_lp10_mp10!AV5) -> 0 | AK5: =ABS(numpy_l10_m0_lp10_mp10!AV5-numpy_l10_m0_lp10_mp10!AW5) -> 0 | AL5: =ABS(numpy_l10_m0_lp10_mp10!AX5-numpy_l10_m0_lp10_mp10!AY5) -> 0 | AM5: =ABS(numpy_l10_m0_lp10_mp10!AX5-numpy_l10_m0_lp10_mp10!AZ5) -> 0 | AN5: =ABS(numpy_l10_m0_lp10_mp10!AZ5-numpy_l10_m0_lp10_mp10!BA5) -> 0
A6: 0.6 | B6: =ABS(numpy_l10_m0_lp10_mp10!B6-numpy_l10_m0_lp10_mp10!C6) -> 0 | C6: =ABS(numpy_l10_m0_lp10_mp10!B6-numpy_l10_m0_lp10_mp10!D6) -> 0.002786919 | D6: =ABS(numpy_l10_m0_lp10_mp10!D6-numpy_l10_m0_lp10_mp10!E6) -> 0 | E6: =ABS(numpy_l10_m0_lp10_mp10!F6-numpy_l10_m0_lp10_mp10!G6) -> 0 | F6: =ABS(numpy_l10_m0_lp10_mp10!F6-numpy_l10_m0_lp10_mp10!H6) -> 1.66001e-05 | G6: =ABS(numpy_l10_m0_lp10_mp10!H6-numpy_l10_m0_lp10_mp10!I6) -> 0 | H6: =ABS(numpy_l10_m0_lp10_mp10!J6-numpy_l10_m0_lp10_mp10!K6) -> 0 | I6: =ABS(numpy_l10_m0_lp10_mp10!J6-numpy_l10_m0_lp10_mp10!L6) -> 1.66001e-05 | J6: =ABS(numpy_l10_m0_lp10_mp10!L6-numpy_l10_m0_lp10_mp10!M6) -> 0 | K6: =ABS(numpy_l10_m0_lp10_mp10!N6-numpy_l10_m0_lp10_mp10!O6) -> 0 | L6: =ABS(numpy_l10_m0_lp10_mp10!N6-numpy_l10_m0_lp10_mp10!P6) -> 4.32e-08 | M6: =ABS(numpy_l10_m0_lp10_mp10!P6-numpy_l10_m0_lp10_mp10!Q6) -> 0 | N6: =ABS(numpy_l10_m0_lp10_mp10!R6-numpy_l10_m0_lp10_mp10!S6) -> 0 | O6: =ABS(numpy_l10_m0_lp10_mp10!R6-numpy_l10_m0_lp10_mp10!T6) -> 4.32e-08 | P6: =ABS(numpy_l10_m0_lp10_mp10!T6-numpy_l10_m0_lp10_mp10!U6) -> 0 | Q6: =ABS(numpy_l10_m0_lp10_mp10!V6-numpy_l10_m0_lp10_mp10!W6) -> 0 | R6: =ABS(numpy_l10_m0_lp10_mp10!V6-numpy_l10_m0_lp10_mp10!X6) -> 1.0000001e-10 | S6: =ABS(numpy_l10_m0_lp10_mp10!X6-numpy_l10_m0_lp10_mp10!Y6) -> 0 | T6: =ABS(numpy_l10_m0_lp10_mp10!Z6-numpy_l10_m0_lp10_mp10!AA6) -> 0 | U6: =ABS(numpy_l10_m0_lp10_mp10!Z6-numpy_l10_m0_lp10_mp10!AB6) -> 1.0000001e-10 | V6: =ABS(numpy_l10_m0_lp10_mp10!AB6-numpy_l10_m0_lp10_mp10!AC6) -> 0 | W6: =ABS(numpy_l10_m0_lp10_mp10!AD6-numpy_l10_m0_lp10_mp10!AE6) -> 1.0000001e-10 | X6: =ABS(numpy_l10_m0_lp10_mp10!AD6-numpy_l10_m0_lp10_mp10!AF6) -> 0 | Y6: =ABS(numpy_l10_m0_lp10_mp10!AF6-numpy_l10_m0_lp10_mp10!AG6) -> 0 | Z6: =ABS(numpy_l10_m0_lp10_mp10!AH6-numpy_l10_m0_lp10_mp10!AI6) -> 1.0000001e-10 | AA6: =ABS(numpy_l10_m0_lp10_mp10!AH6-numpy_l10_m0_lp10_mp10!AJ6) -> 0 | AB6: =ABS(numpy_l10_m0_lp10_mp10!AJ6-numpy_l10_m0_lp10_mp10!AK6) -> 0 | AC6: =ABS(numpy_l10_m0_lp10_mp10!AL6-numpy_l10_m0_lp10_mp10!AM6) -> 1.0000001e-10 | AD6: =ABS(numpy_l10_m0_lp10_mp10!AL6-numpy_l10_m0_lp10_mp10!AN6) -> 0 | AE6: =ABS(numpy_l10_m0_lp10_mp10!AN6-numpy_l10_m0_lp10_mp10!AO6) -> 0 | AF6: =ABS(numpy_l10_m0_lp10_mp10!AP6-numpy_l10_m0_lp10_mp10!AQ6) -> 1.0000001e-10 | AG6: =ABS(numpy_l10_m0_lp10_mp10!AP6-numpy_l10_m0_lp10_mp10!AR6) -> 0 | AH6: =ABS(numpy_l10_m0_lp10_mp10!AR6-numpy_l10_m0_lp10_mp10!AS6) -> 0 | AI6: =ABS(numpy_l10_m0_lp10_mp10!AT6-numpy_l10_m0_lp10_mp10!AU6) -> 1.0000001e-10 | AJ6: =ABS(numpy_l10_m0_lp10_mp10!AT6-numpy_l10_m0_lp10_mp10!AV6) -> 0 | AK6: =ABS(numpy_l10_m0_lp10_mp10!AV6-numpy_l10_m0_lp10_mp10!AW6) -> 0 | AL6: =ABS(numpy_l10_m0_lp10_mp10!AX6-numpy_l10_m0_lp10_mp10!AY6) -> 1.0000001e-10 | AM6: =ABS(numpy_l10_m0_lp10_mp10!AX6-numpy_l10_m0_lp10_mp10!AZ6) -> 0 | AN6: =ABS(numpy_l10_m0_lp10_mp10!AZ6-numpy_l10_m0_lp10_mp10!BA6) -> 0
A7: 0.8 | B7: =ABS(numpy_l10_m0_lp10_mp10!B7-numpy_l10_m0_lp10_mp10!C7) -> 0 | C7: =ABS(numpy_l10_m0_lp10_mp10!B7-numpy_l10_m0_lp10_mp10!D7) -> 0.0048328647 | D7: =ABS(numpy_l10_m0_lp10_mp10!D7-numpy_l10_m0_lp10_mp10!E7) -> 0 | E7: =ABS(numpy_l10_m0_lp10_mp10!F7-numpy_l10_m0_lp10_mp10!G7) -> 0 | F7: =ABS(numpy_l10_m0_lp10_mp10!F7-numpy_l10_m0_lp10_mp10!H7) -> 5.16928e-05 | G7: =ABS(numpy_l10_m0_lp10_mp10!H7-numpy_l10_m0_lp10_mp10!I7) -> 0 | H7: =ABS(numpy_l10_m0_lp10_mp10!J7-numpy_l10_m0_lp10_mp10!K7) -> 0 | I7: =ABS(numpy_l10_m0_lp10_mp10!J7-numpy_l10_m0_lp10_mp10!L7) -> 5.16928e-05 | J7: =ABS(numpy_l10_m0_lp10_mp10!L7-numpy_l10_m0_lp10_mp10!M7) -> 0 | K7: =ABS(numpy_l10_m0_lp10_mp10!N7-numpy_l10_m0_lp10_mp10!O7) -> 0 | L7: =ABS(numpy_l10_m0_lp10_mp10!N7-numpy_l10_m0_lp10_mp10!P7) -> 2.407e-07 | M7: =ABS(numpy_l10_m0_lp10_mp10!P7-numpy_l10_m0_lp10_mp10!Q7) -> 0 | N7: =ABS(numpy_l10_m0_lp10_mp10!R7-numpy_l10_m0_lp10_mp10!S7) -> 0 | O7: =ABS(numpy_l10_m0_lp10_mp10!R7-numpy_l10_m0_lp10_mp10!T7) -> 2.407e-07 | P7: =ABS(numpy_l10_m0_lp10_mp10!T7-numpy_l10_m0_lp10_mp10!U7) -> 0 | Q7: =ABS(numpy_l10_m0_lp10_mp10!V7-numpy_l10_m0_lp10_mp10!W7) -> 0 | R7: =ABS(numpy_l10_m0_lp10_mp10!V7-numpy_l10_m0_lp10_mp10!X7) -> 7e-10 | S7: =ABS(numpy_l10_m0_lp10_mp10!X7-numpy_l10_m0_lp10_mp10!Y7) -> 0 | T7: =ABS(numpy_l10_m0_lp10_mp10!Z7-numpy_l10_m0_lp10_mp10!AA7) -> 0 | U7: =ABS(numpy_l10_m0_lp10_mp10!Z7-numpy_l10_m0_lp10_mp10!AB7) -> 7e-10 | V7: =ABS(numpy_l10_m0_lp10_mp10!AB7-numpy_l10_m0_lp10_mp10!AC7) -> 0 | W7: =ABS(numpy_l10_m0_lp10_mp10!AD7-numpy_l10_m0_lp10_mp10!AE7) -> 0 | X7: =ABS(numpy_l10_m0_lp10_mp10!AD7-numpy_l10_m0_lp10_mp10!AF7) -> 9.9999994e-11 | Y7: =ABS(numpy_l10_m0_lp10_mp10!AF7-numpy_l10_m0_lp10_mp10!AG7) -> 0 | Z7: =ABS(numpy_l10_m0_lp10_mp10!AH7-numpy_l10_m0_lp10_mp10!AI7) -> 0 | AA7: =ABS(numpy_l10_m0_lp10_mp10!AH7-numpy_l10_m0_lp10_mp10!AJ7) -> 9.9999994e-11 | AB7: =ABS(numpy_l10_m0_lp10_mp10!AJ7-numpy_l10_m0_lp10_mp10!AK7) -> 0 | AC7: =ABS(numpy_l10_m0_lp10_mp10!AL7-numpy_l10_m0_lp10_mp10!AM7) -> 0 | AD7: =ABS(numpy_l10_m0_lp10_mp10!AL7-numpy_l10_m0_lp10_mp10!AN7) -> 9.9999994e-11 | AE7: =ABS(numpy_l10_m0_lp10_mp10!AN7-numpy_l10_m0_lp10_mp10!AO7) -> 0 | AF7: =ABS(numpy_l10_m0_lp10_mp10!AP7-numpy_l10_m0_lp10_mp10!AQ7) -> 0 | AG7: =ABS(numpy_l10_m0_lp10_mp10!AP7-numpy_l10_m0_lp10_mp10!AR7) -> 9.9999994e-11 | AH7: =ABS(numpy_l10_m0_lp10_mp10!AR7-numpy_l10_m0_lp10_mp10!AS7) -> 0 | AI7: =ABS(numpy_l10_m0_lp10_mp10!AT7-numpy_l10_m0_lp10_mp10!AU7) -> 0 | AJ7: =ABS(numpy_l10_m0_lp10_mp10!AT7-numpy_l10_m0_lp10_mp10!AV7) -> 9.9999994e-11 | AK7: =ABS(numpy_l10_m0_lp10_mp10!AV7-numpy_l10_m0_lp10_mp10!AW7) -> 0 | AL7: =ABS(numpy_l10_m0_lp10_mp10!AX7-numpy_l10_m0_lp10_mp10!AY7) -> 0 | AM7: =ABS(numpy_l10_m0_lp10_mp10!AX7-numpy_l10_m0_lp10_mp10!AZ7) -> 9.9999994e-11 | AN7: =ABS(numpy_l10_m0_lp10_mp10!AZ7-numpy_l10_m0_lp10_mp10!BA7) -> 0
A8: 1 | B8: =ABS(numpy_l10_m0_lp10_mp10!B8-numpy_l10_m0_lp10_mp10!C8) -> 0 | C8: =ABS(numpy_l10_m0_lp10_mp10!B8-numpy_l10_m0_lp10_mp10!D8) -> 0.0073120089 | D8: =ABS(numpy_l10_m0_lp10_mp10!D8-numpy_l10_m0_lp10_mp10!E8) -> 0 | E8: =ABS(numpy_l10_m0_lp10_mp10!F8-numpy_l10_m0_lp10_mp10!G8) -> 0 | F8: =ABS(numpy_l10_m0_lp10_mp10!F8-numpy_l10_m0_lp10_mp10!H8) -> 0.0001238152 | G8: =ABS(numpy_l10_m0_lp10_mp10!H8-numpy_l10_m0_lp10_mp10!I8) -> 0 | H8: =ABS(numpy_l10_m0_lp10_mp10!J8-numpy_l10_m0_lp10_mp10!K8) -> 0 | I8: =ABS(numpy_l10_m0_lp10_mp10!J8-numpy_l10_m0_lp10_mp10!L8) -> 0.0001238152 | J8: =ABS(numpy_l10_m0_lp10_mp10!L8-numpy_l10_m0_lp10_mp10!M8) -> 0 | K8: =ABS(numpy_l10_m0_lp10_mp10!N8-numpy_l10_m0_lp10_mp10!O8) -> 0 | L8: =ABS(numpy_l10_m0_lp10_mp10!N8-numpy_l10_m0_lp10_mp10!P8) -> 9.059e-07 | M8: =ABS(numpy_l10_m0_lp10_mp10!P8-numpy_l10_m0_lp10_mp10!Q8) -> 0 | N8: =ABS(numpy_l10_m0_lp10_mp10!R8-numpy_l10_m0_lp10_mp10!S8) -> 0 | O8: =ABS(numpy_l10_m0_lp10_mp10!R8-numpy_l10_m0_lp10_mp10!T8) -> 9.059e-07 | P8: =ABS(numpy_l10_m0_lp10_mp10!T8-numpy_l10_m0_lp10_mp10!U8) -> 0 | Q8: =ABS(numpy_l10_m0_lp10_mp10!V8-numpy_l10_m0_lp10_mp10!W8) -> 0 | R8: =ABS(numpy_l10_m0_lp10_mp10!V8-numpy_l10_m0_lp10_mp10!X8) -> 3.8e-09 | S8: =ABS(numpy_l10_m0_lp10_mp10!X8-numpy_l10_m0_lp10_mp10!Y8) -> 0 | T8: =ABS(numpy_l10_m0_lp10_mp10!Z8-numpy_l10_m0_lp10_mp10!AA8) -> 0 | U8: =ABS(numpy_l10_m0_lp10_mp10!Z8-numpy_l10_m0_lp10_mp10!AB8) -> 3.8e-09 | V8: =ABS(numpy_l10_m0_lp10_mp10!AB8-numpy_l10_m0_lp10_mp10!AC8) -> 0 | W8: =ABS(numpy_l10_m0_lp10_mp10!AD8-numpy_l10_m0_lp10_mp10!AE8) -> 0 | X8: =ABS(numpy_l10_m0_lp10_mp10!AD8-numpy_l10_m0_lp10_mp10!AF8) -> 0 | Y8: =ABS(numpy_l10_m0_lp10_mp10!AF8-numpy_l10_m0_lp10_mp10!AG8) -> 0 | Z8: =ABS(numpy_l10_m0_lp10_mp10!AH8-numpy_l10_m0_lp10_mp10!AI8) -> 0 | AA8: =ABS(numpy_l10_m0_lp10_mp10!AH8-numpy_l10_m0_lp10_mp10!AJ8) -> 0 | AB8: =ABS(numpy_l10_m0_lp10_mp10!AJ8-numpy_l10_m0_lp10_mp10!AK8) -> 0 | AC8: =ABS(numpy_l10_m0_lp10_mp10!AL8-numpy_l10_m0_lp10_mp10!AM8) -> 0 | AD8: =ABS(numpy_l10_m0_lp10_mp10!AL8-numpy_l10_m0_lp10_mp10!AN8) -> 1.0000001e-10 | AE8: =ABS(numpy_l10_m0_lp10_mp10!AN8-numpy_l10_m0_lp10_mp10!AO8) -> 0 | AF8: =ABS(numpy_l10_m0_lp10_mp10!AP8-numpy_l10_m0_lp10_mp10!AQ8) -> 0 | AG8: =ABS(numpy_l10_m0_lp10_mp10!AP8-numpy_l10_m0_lp10_mp10!AR8) -> 1.0000001e-10 | AH8: =ABS(numpy_l10_m0_lp10_mp10!AR8-numpy_l10_m0_lp10_mp10!AS8) -> 0 | AI8: =ABS(numpy_l10_m0_lp10_mp10!AT8-numpy_l10_m0_lp10_mp10!AU8) -> 0 | AJ8: =ABS(numpy_l10_m0_lp10_mp10!AT8-numpy_l10_m0_lp10_mp10!AV8) -> 1.0000001e-10 | AK8: =ABS(numpy_l10_m0_lp10_mp10!AV8-numpy_l10_m0_lp10_mp10!AW8) -> 0 | AL8: =ABS(numpy_l10_m0_lp10_mp10!AX8-numpy_l10_m0_lp10_mp10!AY8) -> 0 | AM8: =ABS(numpy_l10_m0_lp10_mp10!AX8-numpy_l10_m0_lp10_mp10!AZ8) -> 1.0000001e-10 | AN8: =ABS(numpy_l10_m0_lp10_mp10!AZ8-numpy_l10_m0_lp10_mp10!BA8) -> 0
A9: 1.2 | B9: =ABS(numpy_l10_m0_lp10_mp10!B9-numpy_l10_m0_lp10_mp10!C9) -> 0 | C9: =ABS(numpy_l10_m0_lp10_mp10!B9-numpy_l10_m0_lp10_mp10!D9) -> 0.010118977 | D9: =ABS(numpy_l10_m0_lp10_mp10!D9-numpy_l10_m0_lp10_mp10!E9) -> 0 | E9: =ABS(numpy_l10_m0_lp10_mp10!F9-numpy_l10_m0_lp10_mp10!G9) -> 0 | F9: =ABS(numpy_l10_m0_lp10_mp10!F9-numpy_l10_m0_lp10_mp10!H9) -> 0.0002507959 | G9: =ABS(numpy_l10_m0_lp10_mp10!H9-numpy_l10_m0_lp10_mp10!I9) -> 0 | H9: =ABS(numpy_l10_m0_lp10_mp10!J9-numpy_l10_m0_lp10_mp10!K9) -> 0 | I9: =ABS(numpy_l10_m0_lp10_mp10!J9-numpy_l10_m0_lp10_mp10!L9) -> 0.0002507959 | J9: =ABS(numpy_l10_m0_lp10_mp10!L9-numpy_l10_m0_lp10_mp10!M9) -> 0 | K9: =ABS(numpy_l10_m0_lp10_mp10!N9-numpy_l10_m0_lp10_mp10!O9) -> 0 | L9: =ABS(numpy_l10_m0_lp10_mp10!N9-numpy_l10_m0_lp10_mp10!P9) -> 2.6607e-06 | M9: =ABS(numpy_l10_m0_lp10_mp10!P9-numpy_l10_m0_lp10_mp10!Q9) -> 0 | N9: =ABS(numpy_l10_m0_lp10_mp10!R9-numpy_l10_m0_lp10_mp10!S9) -> 0 | O9: =ABS(numpy_l10_m0_lp10_mp10!R9-numpy_l10_m0_lp10_mp10!T9) -> 2.6607e-06 | P9: =ABS(numpy_l10_m0_lp10_mp10!T9-numpy_l10_m0_lp10_mp10!U9) -> 0 | Q9: =ABS(numpy_l10_m0_lp10_mp10!V9-numpy_l10_m0_lp10_mp10!W9) -> 0 | R9: =ABS(numpy_l10_m0_lp10_mp10!V9-numpy_l10_m0_lp10_mp10!X9) -> 1.58e-08 | S9: =ABS(numpy_l10_m0_lp10_mp10!X9-numpy_l10_m0_lp10_mp10!Y9) -> 0 | T9: =ABS(numpy_l10_m0_lp10_mp10!Z9-numpy_l10_m0_lp10_mp10!AA9) -> 0 | U9: =ABS(numpy_l10_m0_lp10_mp10!Z9-numpy_l10_m0_lp10_mp10!AB9) -> 1.58e-08 | V9: =ABS(numpy_l10_m0_lp10_mp10!AB9-numpy_l10_m0_lp10_mp10!AC9) -> 0 | W9: =ABS(numpy_l10_m0_lp10_mp10!AD9-numpy_l10_m0_lp10_mp10!AE9) -> 0 | X9: =ABS(numpy_l10_m0_lp10_mp10!AD9-numpy_l10_m0_lp10_mp10!AF9) -> 1.0000001e-10 | Y9: =ABS(numpy_l10_m0_lp10_mp10!AF9-numpy_l10_m0_lp10_mp10!AG9) -> 0 | Z9: =ABS(numpy_l10_m0_lp10_mp10!AH9-numpy_l10_m0_lp10_mp10!AI9) -> 0 | AA9: =ABS(numpy_l10_m0_lp10_mp10!AH9-numpy_l10_m0_lp10_mp10!AJ9) -> 1.0000001e-10 | AB9: =ABS(numpy_l10_m0_lp10_mp10!AJ9-numpy_l10_m0_lp10_mp10!AK9) -> 0 | AC9: =ABS(numpy_l10_m0_lp10_mp10!AL9-numpy_l10_m0_lp10_mp10!AM9) -> 0 | AD9: =ABS(numpy_l10_m0_lp10_mp10!AL9-numpy_l10_m0_lp10_mp10!AN9) -> 0 | AE9: =ABS(numpy_l10_m0_lp10_mp10!AN9-numpy_l10_m0_lp10_mp10!AO9) -> 0 | AF9: =ABS(numpy_l10_m0_lp10_mp10!AP9-numpy_l10_m0_lp10_mp10!AQ9) -> 0 | AG9: =ABS(numpy_l10_m0_lp10_mp10!AP9-numpy_l10_m0_lp10_mp10!AR9) -> 0 | AH9: =ABS(numpy_l10_m0_lp10_mp10!AR9-numpy_l10_m0_lp10_mp10!AS9) -> 0 | AI9: =ABS(numpy_l10_m0_lp10_mp10!AT9-numpy_l10_m0_lp10_mp10!AU9) -> 0 | AJ9: =ABS(numpy_l10_m0_lp10_mp10!AT9-numpy_l10_m0_lp10_mp10!AV9) -> 0 | AK9: =ABS(numpy_l10_m0_lp10_mp10!AV9-numpy_l10_m0_lp10_mp10!AW9) -> 0 | AL9: =ABS(numpy_l10_m0_lp10_mp10!AX9-numpy_l10_m0_lp10_mp10!AY9) -> 0 | AM9: =ABS(numpy_l10_m0_lp10_mp10!AX9-numpy_l10_m0_lp10_mp10!AZ9) -> 0 | AN9: =ABS(numpy_l10_m0_lp10_mp10!AZ9-numpy_l10_m0_lp10_mp10!BA9) -> 0
A10: 1.4 | B10: =ABS(numpy_l10_m0_lp10_mp10!B10-numpy_l10_m0_lp10_mp10!C10) -> 0 | C10: =ABS(numpy_l10_m0_lp10_mp10!B10-numpy_l10_m0_lp10_mp10!D10) -> 0.013133638 | D10: =ABS(numpy_l10_m0_lp10_mp10!D10-numpy_l10_m0_lp10_mp10!E10) -> 0 | E10: =ABS(numpy_l10_m0_lp10_mp10!F10-numpy_l10_m0_lp10_mp10!G10) -> 0 | F10: =ABS(numpy_l10_m0_lp10_mp10!F10-numpy_l10_m0_lp10_mp10!H10) -> 0.0004518806 | G10: =ABS(numpy_l10_m0_lp10_mp10!H10-numpy_l10_m0_lp10_mp10!I10) -> 0 | H10: =ABS(numpy_l10_m0_lp10_mp10!J10-numpy_l10_m0_lp10_mp10!K10) -> 0 | I10: =ABS(numpy_l10_m0_lp10_mp10!J10-numpy_l10_m0_lp10_mp10!L10) -> 0.0004518806 | J10: =ABS(numpy_l10_m0_lp10_mp10!L10-numpy_l10_m0_lp10_mp10!M10) -> 0 | K10: =ABS(numpy_l10_m0_lp10_mp10!N10-numpy_l10_m0_lp10_mp10!O10) -> 0 | L10: =ABS(numpy_l10_m0_lp10_mp10!N10-numpy_l10_m0_lp10_mp10!P10) -> 6.5789e-06 | M10: =ABS(numpy_l10_m0_lp10_mp10!P10-numpy_l10_m0_lp10_mp10!Q10) -> 0 | N10: =ABS(numpy_l10_m0_lp10_mp10!R10-numpy_l10_m0_lp10_mp10!S10) -> 0 | O10: =ABS(numpy_l10_m0_lp10_mp10!R10-numpy_l10_m0_lp10_mp10!T10) -> 6.5789e-06 | P10: =ABS(numpy_l10_m0_lp10_mp10!T10-numpy_l10_m0_lp10_mp10!U10) -> 0 | Q10: =ABS(numpy_l10_m0_lp10_mp10!V10-numpy_l10_m0_lp10_mp10!W10) -> 0 | R10: =ABS(numpy_l10_m0_lp10_mp10!V10-numpy_l10_m0_lp10_mp10!X10) -> 5.36e-08 | S10: =ABS(numpy_l10_m0_lp10_mp10!X10-numpy_l10_m0_lp10_mp10!Y10) -> 0 | T10: =ABS(numpy_l10_m0_lp10_mp10!Z10-numpy_l10_m0_lp10_mp10!AA10) -> 0 | U10: =ABS(numpy_l10_m0_lp10_mp10!Z10-numpy_l10_m0_lp10_mp10!AB10) -> 5.36e-08 | V10: =ABS(numpy_l10_m0_lp10_mp10!AB10-numpy_l10_m0_lp10_mp10!AC10) -> 0 | W10: =ABS(numpy_l10_m0_lp10_mp10!AD10-numpy_l10_m0_lp10_mp10!AE10) -> 1e-10 | X10: =ABS(numpy_l10_m0_lp10_mp10!AD10-numpy_l10_m0_lp10_mp10!AF10) -> 3e-10 | Y10: =ABS(numpy_l10_m0_lp10_mp10!AF10-numpy_l10_m0_lp10_mp10!AG10) -> 0 | Z10: =ABS(numpy_l10_m0_lp10_mp10!AH10-numpy_l10_m0_lp10_mp10!AI10) -> 1e-10 | AA10: =ABS(numpy_l10_m0_lp10_mp10!AH10-numpy_l10_m0_lp10_mp10!AJ10) -> 3e-10 | AB10: =ABS(numpy_l10_m0_lp10_mp10!AJ10-numpy_l10_m0_lp10_mp10!AK10) -> 0 | AC10: =ABS(numpy_l10_m0_lp10_mp10!AL10-numpy_l10_m0_lp10_mp10!AM10) -> 0 | AD10: =ABS(numpy_l10_m0_lp10_mp10!AL10-numpy_l10_m0_lp10_mp10!AN10) -> 0 | AE10: =ABS(numpy_l10_m0_lp10_mp10!AN10-numpy_l10_m0_lp10_mp10!AO10) -> 0 | AF10: =ABS(numpy_l10_m0_lp10_mp10!AP10-numpy_l10_m0_lp10_mp10!AQ10) -> 0 | AG10: =ABS(numpy_l10_m0_lp10_mp10!AP10-numpy_l10_m0_lp10_mp10!AR10) -> 0 | AH10: =ABS(numpy_l10_m0_lp10_mp10!AR10-numpy_l10_m0_lp10_mp10!AS10) -> 0 | AI10: =ABS(numpy_l10_m0_lp10_mp10!AT10-numpy_l10_m0_lp10_mp10!AU10) -> 0 | AJ10: =ABS(numpy_l10_m0_lp10_mp10!AT10-numpy_l10_m0_lp10_mp10!AV10) -> 0 | AK10: =ABS(numpy_l10_m0_lp10_mp10!AV10-numpy_l10_m0_lp10_mp10!AW10) -> 0 | AL10: =ABS(numpy_l10_m0_lp10_mp10!AX10-numpy_l10_m0_lp10_mp10!AY10) -> 0 | AM10: =ABS(numpy_l10_m0_lp10_mp10!AX10-numpy_l10_m0_lp10_mp10!AZ10) -> 0 | AN10: =ABS(numpy_l10_m0_lp10_mp10!AZ10-numpy_l10_m0_lp10_mp10!BA10) -> 0
A11: 1.6 | B11: =ABS(numpy_l10_m0_lp10_mp10!B11-numpy_l10_m0_lp10_mp10!C11) -> 0 | C11: =ABS(numpy_l10_m0_lp10_mp10!B11-numpy_l10_m0_lp10_mp10!D11) -> 0.016225777 | D11: =ABS(numpy_l10_m0_lp10_mp10!D11-numpy_l10_m0_lp10_mp10!E11) -> 0 | E11: =ABS(numpy_l10_m0_lp10_mp10!F11-numpy_l10_m0_lp10_mp10!G11) -> 0 | F11: =ABS(numpy_l10_m0_lp10_mp10!F11-numpy_l10_m0_lp10_mp10!H11) -> 0.0007464023 | G11: =ABS(numpy_l10_m0_lp10_mp10!H11-numpy_l10_m0_lp10_mp10!I11) -> 0 | H11: =ABS(numpy_l10_m0_lp10_mp10!J11-numpy_l10_m0_lp10_mp10!K11) -> 0 | I11: =ABS(numpy_l10_m0_lp10_mp10!J11-numpy_l10_m0_lp10_mp10!L11) -> 0.0007464023 | J11: =ABS(numpy_l10_m0_lp10_mp10!L11-numpy_l10_m0_lp10_mp10!M11) -> 0 | K11: =ABS(numpy_l10_m0_lp10_mp10!N11-numpy_l10_m0_lp10_mp10!O11) -> 0 | L11: =ABS(numpy_l10_m0_lp10_mp10!N11-numpy_l10_m0_lp10_mp10!P11) -> 1.433e-05 | M11: =ABS(numpy_l10_m0_lp10_mp10!P11-numpy_l10_m0_lp10_mp10!Q11) -> 0 | N11: =ABS(numpy_l10_m0_lp10_mp10!R11-numpy_l10_m0_lp10_mp10!S11) -> 0 | O11: =ABS(numpy_l10_m0_lp10_mp10!R11-numpy_l10_m0_lp10_mp10!T11) -> 1.433e-05 | P11: =ABS(numpy_l10_m0_lp10_mp10!T11-numpy_l10_m0_lp10_mp10!U11) -> 0 | Q11: =ABS(numpy_l10_m0_lp10_mp10!V11-numpy_l10_m0_lp10_mp10!W11) -> 0 | R11: =ABS(numpy_l10_m0_lp10_mp10!V11-numpy_l10_m0_lp10_mp10!X11) -> 1.531e-07 | S11: =ABS(numpy_l10_m0_lp10_mp10!X11-numpy_l10_m0_lp10_mp10!Y11) -> 0 | T11: =ABS(numpy_l10_m0_lp10_mp10!Z11-numpy_l10_m0_lp10_mp10!AA11) -> 0 | U11: =ABS(numpy_l10_m0_lp10_mp10!Z11-numpy_l10_m0_lp10_mp10!AB11) -> 1.531e-07 | V11: =ABS(numpy_l10_m0_lp10_mp10!AB11-numpy_l10_m0_lp10_mp10!AC11) -> 0 | W11: =ABS(numpy_l10_m0_lp10_mp10!AD11-numpy_l10_m0_lp10_mp10!AE11) -> 0 | X11: =ABS(numpy_l10_m0_lp10_mp10!AD11-numpy_l10_m0_lp10_mp10!AF11) -> 1.1e-09 | Y11: =ABS(numpy_l10_m0_lp10_mp10!AF11-numpy_l10_m0_lp10_mp10!AG11) -> 0 | Z11: =ABS(numpy_l10_m0_lp10_mp10!AH11-numpy_l10_m0_lp10_mp10!AI11) -> 0 | AA11: =ABS(numpy_l10_m0_lp10_mp10!AH11-numpy_l10_m0_lp10_mp10!AJ11) -> 1.1e-09 | AB11: =ABS(numpy_l10_m0_lp10_mp10!AJ11-numpy_l10_m0_lp10_mp10!AK11) -> 0 | AC11: =ABS(numpy_l10_m0_lp10_mp10!AL11-numpy_l10_m0_lp10_mp10!AM11) -> 0 | AD11: =ABS(numpy_l10_m0_lp10_mp10!AL11-numpy_l10_m0_lp10_mp10!AN11) -> 0 | AE11: =ABS(numpy_l10_m0_lp10_mp10!AN11-numpy_l10_m0_lp10_mp10!AO11) -> 0 | AF11: =ABS(numpy_l10_m0_lp10_mp10!AP11-numpy_l10_m0_lp10_mp10!AQ11) -> 0 | AG11: =ABS(numpy_l10_m0_lp10_mp10!AP11-numpy_l10_m0_lp10_mp10!AR11) -> 0 | AH11: =ABS(numpy_l10_m0_lp10_mp10!AR11-numpy_l10_m0_lp10_mp10!AS11) -> 0 | AI11: =ABS(numpy_l10_m0_lp10_mp10!AT11-numpy_l10_m0_lp10_mp10!AU11) -> 0 | AJ11: =ABS(numpy_l10_m0_lp10_mp10!AT11-numpy_l10_m0_lp10_mp10!AV11) -> 0 | AK11: =ABS(numpy_l10_m0_lp10_mp10!AV11-numpy_l10_m0_lp10_mp10!AW11) -> 0 | AL11: =ABS(numpy_l10_m0_lp10_mp10!AX11-numpy_l10_m0_lp10_mp10!AY11) -> 0 | AM11: =ABS(numpy_l10_m0_lp10_mp10!AX11-numpy_l10_m0_lp10_mp10!AZ11) -> 0 | AN11: =ABS(numpy_l10_m0_lp10_mp10!AZ11-numpy_l10_m0_lp10_mp10!BA11) -> 0
A12: 1.8 | B12: =ABS(numpy_l10_m0_lp10_mp10!B12-numpy_l10_m0_lp10_mp10!C12) -> 0 | C12: =ABS(numpy_l10_m0_lp10_mp10!B12-numpy_l10_m0_lp10_mp10!D12) -> 0.019260163 | D12: =ABS(numpy_l10_m0_lp10_mp10!D12-numpy_l10_m0_lp10_mp10!E12) -> 0 | E12: =ABS(numpy_l10_m0_lp10_mp10!F12-numpy_l10_m0_lp10_mp10!G12) -> 0 | F12: =ABS(numpy_l10_m0_lp10_mp10!F12-numpy_l10_m0_lp10_mp10!H12) -> 0.0011523797 | G12: =ABS(numpy_l10_m0_lp10_mp10!H12-numpy_l10_m0_lp10_mp10!I12) -> 0 | H12: =ABS(numpy_l10_m0_lp10_mp10!J12-numpy_l10_m0_lp10_mp10!K12) -> 0 | I12: =ABS(numpy_l10_m0_lp10_mp10!J12-numpy_l10_m0_lp10_mp10!L12) -> 0.0011523797 | J12: =ABS(numpy_l10_m0_lp10_mp10!L12-numpy_l10_m0_lp10_mp10!M12) -> 0 | K12: =ABS(numpy_l10_m0_lp10_mp10!N12-numpy_l10_m0_lp10_mp10!O12) -> 0 | L12: =ABS(numpy_l10_m0_lp10_mp10!N12-numpy_l10_m0_lp10_mp10!P12) -> 2.83108e-05 | M12: =ABS(numpy_l10_m0_lp10_mp10!P12-numpy_l10_m0_lp10_mp10!Q12) -> 0 | N12: =ABS(numpy_l10_m0_lp10_mp10!R12-numpy_l10_m0_lp10_mp10!S12) -> 0 | O12: =ABS(numpy_l10_m0_lp10_mp10!R12-numpy_l10_m0_lp10_mp10!T12) -> 2.83108e-05 | P12: =ABS(numpy_l10_m0_lp10_mp10!T12-numpy_l10_m0_lp10_mp10!U12) -> 0 | Q12: =ABS(numpy_l10_m0_lp10_mp10!V12-numpy_l10_m0_lp10_mp10!W12) -> 0 | R12: =ABS(numpy_l10_m0_lp10_mp10!V12-numpy_l10_m0_lp10_mp10!X12) -> 3.851e-07 | S12: =ABS(numpy_l10_m0_lp10_mp10!X12-numpy_l10_m0_lp10_mp10!Y12) -> 0 | T12: =ABS(numpy_l10_m0_lp10_mp10!Z12-numpy_l10_m0_lp10_mp10!AA12) -> 0 | U12: =ABS(numpy_l10_m0_lp10_mp10!Z12-numpy_l10_m0_lp10_mp10!AB12) -> 3.851e-07 | V12: =ABS(numpy_l10_m0_lp10_mp10!AB12-numpy_l10_m0_lp10_mp10!AC12) -> 0 | W12: =ABS(numpy_l10_m0_lp10_mp10!AD12-numpy_l10_m0_lp10_mp10!AE12) -> 0 | X12: =ABS(numpy_l10_m0_lp10_mp10!AD12-numpy_l10_m0_lp10_mp10!AF12) -> 3.4e-09 | Y12: =ABS(numpy_l10_m0_lp10_mp10!AF12-numpy_l10_m0_lp10_mp10!AG12) -> 0 | Z12: =ABS(numpy_l10_m0_lp10_mp10!AH12-numpy_l10_m0_lp10_mp10!AI12) -> 0 | AA12: =ABS(numpy_l10_m0_lp10_mp10!AH12-numpy_l10_m0_lp10_mp10!AJ12) -> 3.4e-09 | AB12: =ABS(numpy_l10_m0_lp10_mp10!AJ12-numpy_l10_m0_lp10_mp10!AK12) -> 0 | AC12: =ABS(numpy_l10_m0_lp10_mp10!AL12-numpy_l10_m0_lp10_mp10!AM12) -> 0 | AD12: =ABS(numpy_l10_m0_lp10_mp10!AL12-numpy_l10_m0_lp10_mp10!AN12) -> 0 | AE12: =ABS(numpy_l10_m0_lp10_mp10!AN12-numpy_l10_m0_lp10_mp10!AO12) -> 0 | AF12: =ABS(numpy_l10_m0_lp10_mp10!AP12-numpy_l10_m0_lp10_mp10!AQ12) -> 0 | AG12: =ABS(numpy_l10_m0_lp10_mp10!AP12-numpy_l10_m0_lp10_mp10!AR12) -> 0 | AH12: =ABS(numpy_l10_m0_lp10_mp10!AR12-numpy_l10_m0_lp10_mp10!AS12) -> 0 | AI12: =ABS(numpy_l10_m0_lp10_mp10!AT12-numpy_l10_m0_lp10_mp10!AU12) -> 0 | AJ12: =ABS(numpy_l10_m0_lp10_mp10!AT12-numpy_l10_m0_lp10_mp10!AV12) -> 0 | AK12: =ABS(numpy_l10_m0_lp10_mp10!AV12-numpy_l10_m0_lp10_mp10!AW12) -> 0 | AL12: =ABS(numpy_l10_m0_lp10_mp10!AX12-numpy_l10_m0_lp10_mp10!AY12) -> 0 | AM12: =ABS(numpy_l10_m0_lp10_mp10!AX12-numpy_l10_m0_lp10_mp10!AZ12) -> 0 | AN12: =ABS(numpy_l10_m0_lp10_mp10!AZ12-numpy_l10_m0_lp10_mp10!BA12) -> 0
A13: 2 | B13: =ABS(numpy_l10_m0_lp10_mp10!B13-numpy_l10_m0_lp10_mp10!C13) -> 0 | C13: =ABS(numpy_l10_m0_lp10_mp10!B13-numpy_l10_m0_lp10_mp10!D13) -> 0.022101827 | D13: =ABS(numpy_l10_m0_lp10_mp10!D13-numpy_l10_m0_lp10_mp10!E13) -> 0 | E13: =ABS(numpy_l10_m0_lp10_mp10!F13-numpy_l10_m0_lp10_mp10!G13) -> 0 | F13: =ABS(numpy_l10_m0_lp10_mp10!F13-numpy_l10_m0_lp10_mp10!H13) -> 0.0016851124 | G13: =ABS(numpy_l10_m0_lp10_mp10!H13-numpy_l10_m0_lp10_mp10!I13) -> 0 | H13: =ABS(numpy_l10_m0_lp10_mp10!J13-numpy_l10_m0_lp10_mp10!K13) -> 0 | I13: =ABS(numpy_l10_m0_lp10_mp10!J13-numpy_l10_m0_lp10_mp10!L13) -> 0.0016851124 | J13: =ABS(numpy_l10_m0_lp10_mp10!L13-numpy_l10_m0_lp10_mp10!M13) -> 0 | K13: =ABS(numpy_l10_m0_lp10_mp10!N13-numpy_l10_m0_lp10_mp10!O13) -> 0 | L13: =ABS(numpy_l10_m0_lp10_mp10!N13-numpy_l10_m0_lp10_mp10!P13) -> 5.17513e-05 | M13: =ABS(numpy_l10_m0_lp10_mp10!P13-numpy_l10_m0_lp10_mp10!Q13) -> 0 | N13: =ABS(numpy_l10_m0_lp10_mp10!R13-numpy_l10_m0_lp10_mp10!S13) -> 0 | O13: =ABS(numpy_l10_m0_lp10_mp10!R13-numpy_l10_m0_lp10_mp10!T13) -> 5.17513e-05 | P13: =ABS(numpy_l10_m0_lp10_mp10!T13-numpy_l10_m0_lp10_mp10!U13) -> 0 | Q13: =ABS(numpy_l10_m0_lp10_mp10!V13-numpy_l10_m0_lp10_mp10!W13) -> 0 | R13: =ABS(numpy_l10_m0_lp10_mp10!V13-numpy_l10_m0_lp10_mp10!X13) -> 8.749e-07 | S13: =ABS(numpy_l10_m0_lp10_mp10!X13-numpy_l10_m0_lp10_mp10!Y13) -> 0 | T13: =ABS(numpy_l10_m0_lp10_mp10!Z13-numpy_l10_m0_lp10_mp10!AA13) -> 0 | U13: =ABS(numpy_l10_m0_lp10_mp10!Z13-numpy_l10_m0_lp10_mp10!AB13) -> 8.749e-07 | V13: =ABS(numpy_l10_m0_lp10_mp10!AB13-numpy_l10_m0_lp10_mp10!AC13) -> 0 | W13: =ABS(numpy_l10_m0_lp10_mp10!AD13-numpy_l10_m0_lp10_mp10!AE13) -> 0 | X13: =ABS(numpy_l10_m0_lp10_mp10!AD13-numpy_l10_m0_lp10_mp10!AF13) -> 9.4e-09 | Y13: =ABS(numpy_l10_m0_lp10_mp10!AF13-numpy_l10_m0_lp10_mp10!AG13) -> 0 | Z13: =ABS(numpy_l10_m0_lp10_mp10!AH13-numpy_l10_m0_lp10_mp10!AI13) -> 0 | AA13: =ABS(numpy_l10_m0_lp10_mp10!AH13-numpy_l10_m0_lp10_mp10!AJ13) -> 9.4e-09 | AB13: =ABS(numpy_l10_m0_lp10_mp10!AJ13-numpy_l10_m0_lp10_mp10!AK13) -> 0 | AC13: =ABS(numpy_l10_m0_lp10_mp10!AL13-numpy_l10_m0_lp10_mp10!AM13) -> 0 | AD13: =ABS(numpy_l10_m0_lp10_mp10!AL13-numpy_l10_m0_lp10_mp10!AN13) -> 1e-10 | AE13: =ABS(numpy_l10_m0_lp10_mp10!AN13-numpy_l10_m0_lp10_mp10!AO13) -> 0 | AF13: =ABS(numpy_l10_m0_lp10_mp10!AP13-numpy_l10_m0_lp10_mp10!AQ13) -> 0 | AG13: =ABS(numpy_l10_m0_lp10_mp10!AP13-numpy_l10_m0_lp10_mp10!AR13) -> 0 | AH13: =ABS(numpy_l10_m0_lp10_mp10!AR13-numpy_l10_m0_lp10_mp10!AS13) -> 0 | AI13: =ABS(numpy_l10_m0_lp10_mp10!AT13-numpy_l10_m0_lp10_mp10!AU13) -> 0 | AJ13: =ABS(numpy_l10_m0_lp10_mp10!AT13-numpy_l10_m0_lp10_mp10!AV13) -> 0 | AK13: =ABS(numpy_l10_m0_lp10_mp10!AV13-numpy_l10_m0_lp10_mp10!AW13) -> 0 | AL13: =ABS(numpy_l10_m0_lp10_mp10!AX13-numpy_l10_m0_lp10_mp10!AY13) -> 0 | AM13: =ABS(numpy_l10_m0_lp10_mp10!AX13-numpy_l10_m0_lp10_mp10!AZ13) -> 0 | AN13: =ABS(numpy_l10_m0_lp10_mp10!AZ13-numpy_l10_m0_lp10_mp10!BA13) -> 0
A14: 2.2 | B14: =ABS(numpy_l10_m0_lp10_mp10!B14-numpy_l10_m0_lp10_mp10!C14) -> 0 | C14: =ABS(numpy_l10_m0_lp10_mp10!B14-numpy_l10_m0_lp10_mp10!D14) -> 0.02462134 | D14: =ABS(numpy_l10_m0_lp10_mp10!D14-numpy_l10_m0_lp10_mp10!E14) -> 0 | E14: =ABS(numpy_l10_m0_lp10_mp10!F14-numpy_l10_m0_lp10_mp10!G14) -> 0 | F14: =ABS(numpy_l10_m0_lp10_mp10!F14-numpy_l10_m0_lp10_mp10!H14) -> 0.0023558448 | G14: =ABS(numpy_l10_m0_lp10_mp10!H14-numpy_l10_m0_lp10_mp10!I14) -> 0 | H14: =ABS(numpy_l10_m0_lp10_mp10!J14-numpy_l10_m0_lp10_mp10!K14) -> 0 | I14: =ABS(numpy_l10_m0_lp10_mp10!J14-numpy_l10_m0_lp10_mp10!L14) -> 0.0023558448 | J14: =ABS(numpy_l10_m0_lp10_mp10!L14-numpy_l10_m0_lp10_mp10!M14) -> 0 | K14: =ABS(numpy_l10_m0_lp10_mp10!N14-numpy_l10_m0_lp10_mp10!O14) -> 0 | L14: =ABS(numpy_l10_m0_lp10_mp10!N14-numpy_l10_m0_lp10_mp10!P14) -> 8.87812e-05 | M14: =ABS(numpy_l10_m0_lp10_mp10!P14-numpy_l10_m0_lp10_mp10!Q14) -> 0 | N14: =ABS(numpy_l10_m0_lp10_mp10!R14-numpy_l10_m0_lp10_mp10!S14) -> 0 | O14: =ABS(numpy_l10_m0_lp10_mp10!R14-numpy_l10_m0_lp10_mp10!T14) -> 8.87812e-05 | P14: =ABS(numpy_l10_m0_lp10_mp10!T14-numpy_l10_m0_lp10_mp10!U14) -> 0 | Q14: =ABS(numpy_l10_m0_lp10_mp10!V14-numpy_l10_m0_lp10_mp10!W14) -> 0 | R14: =ABS(numpy_l10_m0_lp10_mp10!V14-numpy_l10_m0_lp10_mp10!X14) -> 1.8297e-06 | S14: =ABS(numpy_l10_m0_lp10_mp10!X14-numpy_l10_m0_lp10_mp10!Y14) -> 0 | T14: =ABS(numpy_l10_m0_lp10_mp10!Z14-numpy_l10_m0_lp10_mp10!AA14) -> 0 | U14: =ABS(numpy_l10_m0_lp10_mp10!Z14-numpy_l10_m0_lp10_mp10!AB14) -> 1.8297e-06 | V14: =ABS(numpy_l10_m0_lp10_mp10!AB14-numpy_l10_m0_lp10_mp10!AC14) -> 0 | W14: =ABS(numpy_l10_m0_lp10_mp10!AD14-numpy_l10_m0_lp10_mp10!AE14) -> 0 | X14: =ABS(numpy_l10_m0_lp10_mp10!AD14-numpy_l10_m0_lp10_mp10!AF14) -> 2.41e-08 | Y14: =ABS(numpy_l10_m0_lp10_mp10!AF14-numpy_l10_m0_lp10_mp10!AG14) -> 0 | Z14: =ABS(numpy_l10_m0_lp10_mp10!AH14-numpy_l10_m0_lp10_mp10!AI14) -> 0 | AA14: =ABS(numpy_l10_m0_lp10_mp10!AH14-numpy_l10_m0_lp10_mp10!AJ14) -> 2.41e-08 | AB14: =ABS(numpy_l10_m0_lp10_mp10!AJ14-numpy_l10_m0_lp10_mp10!AK14) -> 0 | AC14: =ABS(numpy_l10_m0_lp10_mp10!AL14-numpy_l10_m0_lp10_mp10!AM14) -> 0 | AD14: =ABS(numpy_l10_m0_lp10_mp10!AL14-numpy_l10_m0_lp10_mp10!AN14) -> 2e-10 | AE14: =ABS(numpy_l10_m0_lp10_mp10!AN14-numpy_l10_m0_lp10_mp10!AO14) -> 0 | AF14: =ABS(numpy_l10_m0_lp10_mp10!AP14-numpy_l10_m0_lp10_mp10!AQ14) -> 0 | AG14: =ABS(numpy_l10_m0_lp10_mp10!AP14-numpy_l10_m0_lp10_mp10!AR14) -> 0 | AH14: =ABS(numpy_l10_m0_lp10_mp10!AR14-numpy_l10_m0_lp10_mp10!AS14) -> 0 | AI14: =ABS(numpy_l10_m0_lp10_mp10!AT14-numpy_l10_m0_lp10_mp10!AU14) -> 0 | AJ14: =ABS(numpy_l10_m0_lp10_mp10!AT14-numpy_l10_m0_lp10_mp10!AV14) -> 0 | AK14: =ABS(numpy_l10_m0_lp10_mp10!AV14-numpy_l10_m0_lp10_mp10!AW14) -> 0 | AL14: =ABS(numpy_l10_m0_lp10_mp10!AX14-numpy_l10_m0_lp10_mp10!AY14) -> 0 | AM14: =ABS(numpy_l10_m0_lp10_mp10!AX14-numpy_l10_m0_lp10_mp10!AZ14) -> 0 | AN14: =ABS(numpy_l10_m0_lp10_mp10!AZ14-numpy_l10_m0_lp10_mp10!BA14) -> 0
... A253: 50 | B253: =ABS(numpy_l10_m0_lp10_mp10!B253-numpy_l10_m0_lp10_mp10!C253) -> 0 | C253: =ABS(numpy_l10_m0_lp10_mp10!B253-numpy_l10_m0_lp10_mp10!D253) -> 0.0036367906 | D253: =ABS(numpy_l10_m0_lp10_mp10!D253-numpy_l10_m0_lp10_mp10!E253) -> 0 | E253: =ABS(numpy_l10_m0_lp10_mp10!F253-numpy_l10_m0_lp10_mp10!G253) -> 0 | F253: =ABS(numpy_l10_m0_lp10_mp10!F253-numpy_l10_m0_lp10_mp10!H253) -> 0.0041262278 | G253: =ABS(numpy_l10_m0_lp10_mp10!H253-numpy_l10_m0_lp10_mp10!I253) -> 0 | H253: =ABS(numpy_l10_m0_lp10_mp10!J253-numpy_l10_m0_lp10_mp10!K253) -> 0 | I253: =ABS(numpy_l10_m0_lp10_mp10!J253-numpy_l10_m0_lp10_mp10!L253) -> 0.0041262278 | J253: =ABS(numpy_l10_m0_lp10_mp10!L253-numpy_l10_m0_lp10_mp10!M253) -> 0 | K253: =ABS(numpy_l10_m0_lp10_mp10!N253-numpy_l10_m0_lp10_mp10!O253) -> 0 | L253: =ABS(numpy_l10_m0_lp10_mp10!N253-numpy_l10_m0_lp10_mp10!P253) -> 0.0042877677 | M253: =ABS(numpy_l10_m0_lp10_mp10!P253-numpy_l10_m0_lp10_mp10!Q253) -> 0 | N253: =ABS(numpy_l10_m0_lp10_mp10!R253-numpy_l10_m0_lp10_mp10!S253) -> 0 | O253: =ABS(numpy_l10_m0_lp10_mp10!R253-numpy_l10_m0_lp10_mp10!T253) -> 0.0042877677 | P253: =ABS(numpy_l10_m0_lp10_mp10!T253-numpy_l10_m0_lp10_mp10!U253) -> 0 | Q253: =ABS(numpy_l10_m0_lp10_mp10!V253-numpy_l10_m0_lp10_mp10!W253) -> 0 | R253: =ABS(numpy_l10_m0_lp10_mp10!V253-numpy_l10_m0_lp10_mp10!X253) -> 0.0038936 | S253: =ABS(numpy_l10_m0_lp10_mp10!X253-numpy_l10_m0_lp10_mp10!Y253) -> 0 | T253: =ABS(numpy_l10_m0_lp10_mp10!Z253-numpy_l10_m0_lp10_mp10!AA253) -> 0 | U253: =ABS(numpy_l10_m0_lp10_mp10!Z253-numpy_l10_m0_lp10_mp10!AB253) -> 0.0038936 | V253: =ABS(numpy_l10_m0_lp10_mp10!AB253-numpy_l10_m0_lp10_mp10!AC253) -> 0 | W253: =ABS(numpy_l10_m0_lp10_mp10!AD253-numpy_l10_m0_lp10_mp10!AE253) -> 2e-10 | X253: =ABS(numpy_l10_m0_lp10_mp10!AD253-numpy_l10_m0_lp10_mp10!AF253) -> 0.0027194276 | Y253: =ABS(numpy_l10_m0_lp10_mp10!AF253-numpy_l10_m0_lp10_mp10!AG253) -> 0 | Z253: =ABS(numpy_l10_m0_lp10_mp10!AH253-numpy_l10_m0_lp10_mp10!AI253) -> 2e-10 | AA253: =ABS(numpy_l10_m0_lp10_mp10!AH253-numpy_l10_m0_lp10_mp10!AJ253) -> 0.0027194276 | AB253: =ABS(numpy_l10_m0_lp10_mp10!AJ253-numpy_l10_m0_lp10_mp10!AK253) -> 0 | AC253: =ABS(numpy_l10_m0_lp10_mp10!AL253-numpy_l10_m0_lp10_mp10!AM253) -> 3e-10 | AD253: =ABS(numpy_l10_m0_lp10_mp10!AL253-numpy_l10_m0_lp10_mp10!AN253) -> 0.0006173223 | AE253: =ABS(numpy_l10_m0_lp10_mp10!AN253-numpy_l10_m0_lp10_mp10!AO253) -> 0 | AF253: =ABS(numpy_l10_m0_lp10_mp10!AP253-numpy_l10_m0_lp10_mp10!AQ253) -> 2e-09 | AG253: =ABS(numpy_l10_m0_lp10_mp10!AP253-numpy_l10_m0_lp10_mp10!AR253) -> 0.0023349297 | AH253: =ABS(numpy_l10_m0_lp10_mp10!AR253-numpy_l10_m0_lp10_mp10!AS253) -> 0 | AI253: =ABS(numpy_l10_m0_lp10_mp10!AT253-numpy_l10_m0_lp10_mp10!AU253) -> 2.14964e-05 | AJ253: =ABS(numpy_l10_m0_lp10_mp10!AT253-numpy_l10_m0_lp10_mp10!AV253) -> 0.0002466546 | AK253: =ABS(numpy_l10_m0_lp10_mp10!AV253-numpy_l10_m0_lp10_mp10!AW253) -> 0 | AL253: =ABS(numpy_l10_m0_lp10_mp10!AX253-numpy_l10_m0_lp10_mp10!AY253) -> 0.011265153 | AM253: =ABS(numpy_l10_m0_lp10_mp10!AX253-numpy_l10_m0_lp10_mp10!AZ253) -> 0.0055255692 | AN253: =ABS(numpy_l10_m0_lp10_mp10!AZ253-numpy_l10_m0_lp10_mp10!BA253) -> 0

Sheet A1 - A2 - numpy_l10_m0_lp10_mp0
B1: kmax1 | C1: kmax2 | D1: kmax4 | E1: kmax6 | F1: kmax8 | G1: kmax10 | H1: kmax12 | I1: kmax25 | J1: kmax30 | K1: kmax1 | L1: kmax2 | M1: kmax4 | N1: kmax6 | O1: kmax8 | P1: kmax10 | Q1: kmax12
A2: a | B2: |A1 - A2| | C2: |A1 - A2| | D2: |A1 - A2| | E2: |A1 - A2| | F2: |A1 - A2| | G2: |A1 - A2| | H2: |A1 - A2| | I2: |A1 - A2| | J2: |A1 - A2| | K2: log |A1 - A2| | L2: log |A1 - A2| | M2: log |A1 - A2| | N2: log |A1 - A2| | O2: log |A1 - A2| | P2: log |A1 - A2| | Q2: log |A1 - A2|
A3: 0 | B3: 0 | C3: 0 | D3: 0 | E3: 0 | F3: 0 | G3: 0 | H3: 0 | I3: 0 | J3: 0
A4: 0.2 | B4: 0 | C4: 0 | D4: 0 | E4: 0 | F4: 0 | G4: 0 | H4: 0 | I4: 0 | J4: 0
A5: 0.4 | B5: 0 | C5: 0 | D5: 0 | E5: 0 | F5: 0 | G5: 0 | H5: 0 | I5: 0 | J5: 0
A6: 0.6 | B6: 0 | C6: 0 | D6: 0 | E6: 0 | F6: 1.0000001e-10 | G6: 1.0000001e-10 | H6: 1.0000001e-10 | I6: 1.0000001e-10 | J6: 1.0000001e-10
A7: 0.8 | B7: 0 | C7: 0 | D7: 0 | E7: 0 | F7: 0 | G7: 0 | H7: 0 | I7: 0 | J7: 0
A8: 1 | B8: 0 | C8: 0 | D8: 0 | E8: 0 | F8: 0 | G8: 0 | H8: 0 | I8: 0 | J8: 0
A9: 1.2 | B9: 0 | C9: 0 | D9: 0 | E9: 0 | F9: 0 | G9: 0 | H9: 0 | I9: 0 | J9: 0
A10: 1.4 | B10: 0 | C10: 0 | D10: 0 | E10: 0 | F10: 1e-10 | G10: 0 | H10: 0 | I10: 0 | J10: 0
A11: 1.6 | B11: 0 | C11: 0 | D11: 0 | E11: 0 | F11: 0 | G11: 0 | H11: 0 | I11: 0 | J11: 0
A12: 1.8 | B12: 0 | C12: 0 | D12: 0 | E12: 0 | F12: 0 | G12: 0 | H12: 0 | I12: 0 | J12: 0
A13: 2 | B13: 0 | C13: 0 | D13: 0 | E13: 0 | F13: 0 | G13: 0 | H13: 0 | I13: 0 | J13: 0
A14: 2.2 | B14: 0 | C14: 0 | D14: 0 | E14: 0 | F14: 0 | G14: 0 | H14: 0 | I14: 0 | J14: 0
... A17: 2.8 | B17: 0 | C17: 1e-10 | D17: 0 | E17: 0 | F17: 0 | G17: 0 | H17: 0 | I17: 0 | J17: 0
A18: 3 | B18: 0 | C18: 0 | D18: 0 | E18: 0 | F18: 1e-10 | G18: 0 | H18: 0 | I18: 0 | J18: 0 | K18: =LOG(B18) -> #NUM! | L18: =LOG(C18) -> #NUM! | M18: =LOG(D18) -> #NUM! | N18: =LOG(E18) -> #NUM! | O18: =LOG(F18) -> -10 | P18: =LOG(G18) -> #NUM! | Q18: =LOG(H18) -> #NUM!
A19: 3.2 | B19: 0 | C19: 0 | D19: 0 | E19: 0 | F19: 0 | G19: 0 | H19: 0 | I19: 0 | J19: 0 | K19: =LOG(B19) -> #NUM! | L19: =LOG(C19) -> #NUM! | M19: =LOG(D19) -> #NUM! | N19: =LOG(E19) -> #NUM! | O19: =LOG(F19) -> #NUM! | P19: =LOG(G19) -> #NUM! | Q19: =LOG(H19) -> #NUM!
A20: 3.4 | B20: 0 | C20: 0 | D20: 0 | E20: 0 | F20: 0 | G20: 1e-10 | H20: 0 | I20: 0 | J20: 0 | K20: =LOG(B20) -> #NUM! | L20: =LOG(C20) -> #NUM! | M20: =LOG(D20) -> #NUM! | N20: =LOG(E20) -> #NUM! | O20: =LOG(F20) -> #NUM! | P20: =LOG(G20) -> -10 | Q20: =LOG(H20) -> #NUM!
A21: 3.6 | B21: 0 | C21: 1e-10 | D21: 0 | E21: 0 | F21: 0 | G21: 0 | H21: 0 | I21: 0 | J21: 0 | K21: =LOG(B21) -> #NUM! | L21: =LOG(C21) -> -10 | M21: =LOG(D21) -> #NUM! | N21: =LOG(E21) -> #NUM! | O21: =LOG(F21) -> #NUM! | P21: =LOG(G21) -> #NUM! | Q21: =LOG(H21) -> #NUM!
A22: 3.8 | B22: 0 | C22: 0 | D22: 0 | E22: 0 | F22: 1e-10 | G22: 0 | H22: 0 | I22: 1e-10 | J22: 1e-10 | K22: =LOG(B22) -> #NUM! | L22: =LOG(C22) -> #NUM! | M22: =LOG(D22) -> #NUM! | N22: =LOG(E22) -> #NUM! | O22: =LOG(F22) -> -10 | P22: =LOG(G22) -> #NUM! | Q22: =LOG(H22) -> #NUM!
A23: 4 | B23: 0 | C23: 0 | D23: 0 | E23: 1e-10 | F23: 0 | G23: 0 | H23: 1e-10 | I23: 1e-10 | J23: 1e-10 | K23: =LOG(B23) -> #NUM! | L23: =LOG(C23) -> #NUM! | M23: =LOG(D23) -> #NUM! | N23: =LOG(E23) -> -10 | O23: =LOG(F23) -> #NUM! | P23: =LOG(G23) -> #NUM! | Q23: =LOG(H23) -> -10
A24: 4.2 | B24: 0 | C24: 0 | D24: 0 | E24: 1e-10 | F24: 0 | G24: 1e-10 | H24: 1e-10 | I24: 1e-10 | J24: 1e-10 | K24: =LOG(B24) -> #NUM! | L24: =LOG(C24) -> #NUM! | M24: =LOG(D24) -> #NUM! | N24: =LOG(E24) -> -10 | O24: =LOG(F24) -> #NUM! | P24: =LOG(G24) -> -10 | Q24: =LOG(H24) -> -10
A25: 4.4 | B25: 0 | C25: 0 | D25: 0 | E25: 0 | F25: 1e-10 | G25: 1e-10 | H25: 1e-10 | I25: 1e-10 | J25: 1e-10 | K25: =LOG(B25) -> #NUM! | L25: =LOG(C25) -> #NUM! | M25: =LOG(D25) -> #NUM! | N25: =LOG(E25) -> #NUM! | O25: =LOG(F25) -> -10 | P25: =LOG(G25) -> -10 | Q25: =LOG(H25) -> -10
A26: 4.6 | B26: 0 | C26: 0 | D26: 1e-10 | E26: 0 | F26: 9.9999998e-11 | G26: 9.9999998e-11 | H26: 9.9999998e-11 | I26: 1e-10 | J26: 1e-10 | K26: =LOG(B26) -> #NUM! | L26: =LOG(C26) -> #NUM! | M26: =LOG(D26) -> -10 | N26: =LOG(E26) -> #NUM! | O26: =LOG(F26) -> -10 | P26: =LOG(G26) -> -10 | Q26: =LOG(H26) -> -10
A27: 4.8 | B27: 0 | C27: 0 | D27: 0 | E27: 1e-10 | F27: 2e-10 | G27: 9.9999998e-11 | H27: 1e-10 | I27: 2e-10 | J27: 2e-10 | K27: =LOG(B27) -> #NUM! | L27: =LOG(C27) -> #NUM! | M27: =LOG(D27) -> #NUM! | N27: =LOG(E27) -> -10 | O27: =LOG(F27) -> -9.69897 | P27: =LOG(G27) -> -10 | Q27: =LOG(H27) -> -10
A28: 5 | B28: 0 | C28: 0 | D28: 0 | E28: 9.9999998e-11 | F28: 2e-10 | G28: 1e-10 | H28: 2e-10 | I28: 1e-10 | J28: 1e-10 | K28: =LOG(B28) -> #NUM! | L28: =LOG(C28) -> #NUM! | M28: =LOG(D28) -> #NUM! | N28: =LOG(E28) -> -10 | O28: =LOG(F28) -> -9.69897 | P28: =LOG(G28) -> -10 | Q28: =LOG(H28) -> -9.69897
A29: 5.2 | B29: 0 | C29: 0 | D29: 0 | E29: 0 | F29: 2e-10 | G29: 3e-10 | H29: 3e-10 | I29: 2e-10 | J29: 2e-10 | K29: =LOG(B29) -> #NUM! | L29: =LOG(C29) -> #NUM! | M29: =LOG(D29) -> #NUM! | N29: =LOG(E29) -> #NUM! | O29: =LOG(F29) -> -9.69897 | P29: =LOG(G29) -> -9.5228787 | Q29: =LOG(H29) -> -9.5228787
... A253: 50 | B253: 0 | C253: 0 | D253: 0 | E253: 0 | F253: 2e-10 | G253: 3e-10 | H253: 2e-09 | I253: 2.14964e-05 | J253: 0.011265153 | K253: =LOG(B253) -> #NUM! | L253: =LOG(C253) -> #NUM! | M253: =LOG(D253) -> #NUM! | N253: =LOG(E253) -> #NUM! | O253: =LOG(F253) -> -9.69897 | P253: =LOG(G253) -> -9.5228787 | Q253: =LOG(H253) -> -8.69897

Sheet A1 - M0 - numpy_l10_m0_lp10_mp0
B1: kmax1 | C1: kmax2 | D1: kmax4 | E1: kmax6 | F1: kmax8 | G1: kmax10 | H1: kmax12 | I1: kmax25 | J1: kmax30 | K1: kmax1 | L1: kmax2 | M1: kmax4 | N1: kmax6 | O1: kmax8 | P1: kmax10 | Q1: kmax12
A2: a | B2: |A1 - M0| | C2: |A1 - M0| | D2: |A1 - M0| | E2: |A1 - M0| | F2: |A1 - M0| | G2: |A1 - M0| | H2: |A1 - M0| | I2: |A1 - M0| | J2: |A1 - M0| | K2: log |A1 - M0| | L2: log |A1 - M0| | M2: log |A1 - M0| | N2: log |A1 - M0| | O2: log |A1 - M0| | P2: log |A1 - M0| | Q2: log |A1 - M0|
A3: 0 | B3: 0 | C3: 0 | D3: 0 | E3: 0 | F3: 0 | G3: 0 | H3: 0 | I3: 0 | J3: 0
A4: 0.2 | B4: 0.000318519 | C4: 2.084e-07 | D4: 1.0000001e-10 | E4: 0 | F4: 0 | G4: 0 | H4: 0 | I4: 0 | J4: 0
A5: 0.4 | B5: 0.0012606976 | C5: 3.3138e-06 | D5: 3.9e-09 | E5: 0 | F5: 0 | G5: 0 | H5: 0 | I5: 0 | J5: 0
A6: 0.6 | B6: 0.002786919 | C6: 1.66001e-05 | D6: 4.32e-08 | E6: 1.0000001e-10 | F6: 0 | G6: 0 | H6: 0 | I6: 0 | J6: 0
A7: 0.8 | B7: 0.0048328647 | C7: 5.16928e-05 | D7: 2.407e-07 | E7: 7e-10 | F7: 9.9999994e-11 | G7: 9.9999994e-11 | H7: 9.9999994e-11 | I7: 9.9999994e-11 | J7: 9.9999994e-11
